Workbook

Sheet compare
A1: 10 base
A2: # Contrast | B2: # Possible | C2: Total Sig | D2: #Uni Sig | E2: #Pre Sig | F2: Total Rel | G2: #Uni Rel | H2: #Pre Rel | I2: #pv | J2: #v | K2: #cls | L2: runtime
A3: =AVERAGE('10 base'!C:C) -> 7.2432 | B3: =AVERAGE('10 base'!D:D) -> 8.2608 | C3: =AVERAGE('10 base'!E:E) -> 5.2752 | D3: =AVERAGE('10 base'!F:F) -> 4.6544 | E3: =AVERAGE('10 base'!G:G) -> 9 | F3: =AVERAGE('10 base'!H:H) -> 3.256 | G3: =AVERAGE('10 base'!I:I) -> 2.784 | H3: =AVERAGE('10 base'!J:J) -> 5.6464 | I3: =AVERAGE('10 base'!K:K) -> 161.3552 | J3: =AVERAGE('10 base'!L:L) -> 1421.6832 | K3: =AVERAGE('10 base'!M:M) -> 2430.1104 | L3: =AVERAGE('10 base'!N:N) -> 234.4112
A5: 10 target
A6: # Contrast | B6: # Possible | C6: Total Sig | D6: #Uni Sig | E6: #Pre Sig | F6: Total Rel | G6: #Uni Rel | H6: #Pre Rel | I6: #pv | J6: #v | K6: #cls | L6: runtime
A7: =AVERAGE('10 target'!C:C) -> 7.1712 | B7: =AVERAGE('10 target'!D:D) -> 8.2608 | C7: =AVERAGE('10 target'!E:E) -> 5.2752 | D7: =AVERAGE('10 target'!F:F) -> 3.9824 | E7: =AVERAGE('10 target'!G:G) -> 6.5376 | F7: =AVERAGE('10 target'!H:H) -> 3.256 | G7: =AVERAGE('10 target'!I:I) -> 1.9168 | H7: =AVERAGE('10 target'!J:J) -> 2.6768 | I7: =AVERAGE('10 target'!K:K) -> 164.7136 | J7: =AVERAGE('10 target'!L:L) -> 1463.4576 | K7: =AVERAGE('10 target'!M:M) -> 2555.5088 | L7: =AVERAGE('10 target'!N:N) -> 291.9088
A9: 5 base
A10: # Contrast | B10: # Possible | C10: Total Sig | D10: #Uni Sig | E10: #Pre Sig | F10: Total Rel | G10: #Uni Rel | H10: #Pre Rel | I10: #pv | J10: #v | K10: #cls | L10: runtime
A11: =AVERAGE('5 base'!C:C) -> 4.3056 | B11: =AVERAGE('5 base'!D:D) -> 4.6624 | C11: =AVERAGE('5 base'!E:E) -> 5.2752 | D11: =AVERAGE('5 base'!F:F) -> 4.88 | E11: =AVERAGE('5 base'!G:G) -> 9.0208 | F11: =AVERAGE('5 base'!H:H) -> 3.256 | G11: =AVERAGE('5 base'!I:I) -> 2.888 | H11: =AVERAGE('5 base'!J:J) -> 6.4464 | I11: =AVERAGE('5 base'!K:K) -> 83.7984 | J11: =AVERAGE('5 base'!L:L) -> 784.56 | K11: =AVERAGE('5 base'!M:M) -> 1296.0752 | L11: =AVERAGE('5 base'!N:N) -> 66.0208
A13: 5 target
A14: # Contrast | B14: # Possible | C14: Total Sig | D14: #Uni Sig | E14: #Pre Sig | F14: Total Rel | G14: #Uni Rel | H14: #Pre Rel | I14: #pv | J14: #v | K14: #cls | L14: runtime
A15: =AVERAGE('5 target'!C:C) -> 4.2144 | B15: =AVERAGE('5 target'!D:D) -> 4.6624 | C15: =AVERAGE('5 target'!E:E) -> 5.2752 | D15: =AVERAGE('5 target'!F:F) -> 3.4928 | E15: =AVERAGE('5 target'!G:G) -> 5.1808 | F15: =AVERAGE('5 target'!H:H) -> 3.256 | G15: =AVERAGE('5 target'!I:I) -> 1.4192 | H15: =AVERAGE('5 target'!J:J) -> 1.8112 | I15: =AVERAGE('5 target'!K:K) -> 87.0144 | J15: =AVERAGE('5 target'!L:L) -> 822.0864 | K15: =AVERAGE('5 target'!M:M) -> 1408.9568 | L15: =AVERAGE('5 target'!N:N) -> 91.616
A29: Strat | B29: Expr | D29: Sigs in Instance | F29: Rels in Instance | H29: SAT Problem Size | K29: T[ms] | M29: # Sug | N29: From Model Struct | P29: From Base Strat
B30: #Sug | C30: #Differ | D30: #Uni | E30: Total | F30: #Uni | G30: Toal | H30: #PV | I30: #V | J30: #Cls | N30: Sigs | O30: Rels | P30: Sigs | Q30: Rels
A31: Base | B31: =B11 -> 4.6624 | C31: =A11 -> 4.3056 | D31: =D11 -> 4.88 | E31: =E11 -> 9.0208 | F31: =G11 -> 2.888 | G31: =H11 -> 6.4464 | H31: =I11 -> 83.7984 | I31: =J11 -> 784.56 | J31: =K11 -> 1296.0752 | K31: =L11 -> 66.0208 | M31: 5 | N31: =(C15-D15)/C15*100 -> 33.788292 | O31: =(F15-G15)/F15*100 -> 56.412776 | P31: =(E11-E15)/E11*100 -> 42.568287 | Q31: =(H11-H15)/H11*100 -> 71.903698
A32: Target | C32: =A15 -> 4.2144 | D32: =D15 -> 3.4928 | E32: =E15 -> 5.1808 | F32: =G15 -> 1.4192 | G32: =H15 -> 1.8112 | H32: =I15 -> 87.0144 | I32: =J15 -> 822.0864 | J32: =K15 -> 1408.9568 | K32: =L15 -> 91.616 | M32: 10 | N32: =(C7-D7)/C7*100 -> 24.507128 | O32: =(F7-G7)/F7*100 -> 41.130221 | P32: =(E3-E7)/E3*100 -> 27.36 | Q32: =(H3-H7)/H3*100 -> 52.592802
A33: Base | B33: =B3 -> 8.2608 | C33: =A3 -> 7.2432 | D33: =D3 -> 4.6544 | E33: =E3 -> 9 | F33: =G3 -> 2.784 | G33: =H3 -> 5.6464 | H33: =I3 -> 161.3552 | I33: =J3 -> 1421.6832 | J33: =K3 -> 2430.1104 | K33: =L3 -> 234.4112
A34: Target | C34: =A7 -> 7.1712 | D34: =D7 -> 3.9824 | E34: =E7 -> 6.5376 | F34: =G7 -> 1.9168 | G34: =H7 -> 2.6768 | H34: =I7 -> 164.7136 | I34: =J7 -> 1463.4576 | J34: =K7 -> 2555.5088 | K34: =L7 -> 291.9088

Sheet 5 base
A1: array | B1: array-l12-c18.result.json | C1: 4 | D1: 4 | E1: 2 | F1: 2 | G1: 2 | H1: 2 | I1: 2 | J1: 8 | K1: 67 | L1: 620 | M1: 1261 | N1: 210 | O1: 19 | P1: 183 | Q1: Element={Element$0}Array={Array$0}i2e={Array$0->0->Element$0 | R1: Array$0->1->Element$0 | S1: Array$0->2->Element$0 | T1: Array$0->3->Element$0 | U1: Array$0->4->Element$0 | V1: Array$0->5->Element$0 | W1: Array$0->6->Element$0}length={Array$0->7}
A2: array | B2: array-l18-c8.result.json | C2: 4 | D2: 4 | E2: 2 | F2: 2 | G2: 2 | H2: 2 | I2: 2 | J2: 8 | K2: 67 | L2: 620 | M2: 1261 | N2: 55 | O2: 12 | P2: 40 | Q2: Element={Element$0}Array={Array$0}i2e={Array$0->0->Element$0 | R2: Array$0->1->Element$0 | S2: Array$0->2->Element$0 | T2: Array$0->3->Element$0 | U2: Array$0->4->Element$0 | V2: Array$0->5->Element$0 | W2: Array$0->6->Element$0}length={Array$0->7}
A3: array | B3: array-l24-c17.result.json | C3: 4 | D3: 4 | E3: 2 | F3: 2 | G3: 2 | H3: 2 | I3: 2 | J3: 8 | K3: 83 | L3: 686 | M3: 1371 | N3: 64 | O3: 13 | P3: 48 | Q3: Element={Element$0}Array={Array$0}i2e={Array$0->0->Element$0 | R3: Array$0->1->Element$0 | S3: Array$0->2->Element$0 | T3: Array$0->3->Element$0 | U3: Array$0->4->Element$0 | V3: Array$0->5->Element$0 | W3: Array$0->6->Element$0}length={Array$0->7}
A4: array | B4: array-l24-c21.result.json | C4: 4 | D4: 4 | E4: 2 | F4: 2 | G4: 2 | H4: 2 | I4: 2 | J4: 6 | K4: 115 | L4: 789 | M4: 1532 | N4: 60 | O4: 13 | P4: 44 | Q4: Element={Element$0}Array={Array$0}i2e={Array$0->2->Element$0 | R4: Array$0->3->Element$0 | S4: Array$0->4->Element$0 | T4: Array$0->5->Element$0 | U4: Array$0->6->Element$0}length={Array$0->7}
A5: array | B5: array-l24-c55.result.json | C5: 5 | D5: 5 | E5: 2 | F5: 2 | G5: 2 | H5: 2 | I5: 2 | J5: 8 | K5: 99 | L5: 773 | M5: 1569 | N5: 39 | O5: 12 | P5: 23 | Q5: Element={Element$0}Array={Array$0}i2e={Array$0->0->Element$0 | R5: Array$0->1->Element$0 | S5: Array$0->2->Element$0 | T5: Array$0->3->Element$0 | U5: Array$0->4->Element$0 | V5: Array$0->5->Element$0 | W5: Array$0->6->Element$0}length={Array$0->7}
A6: array | B6: array-l31-c17.result.json | C6: 4 | D6: 4 | E6: 2 | F6: 2 | G6: 2 | H6: 2 | I6: 2 | J6: 8 | K6: 83 | L6: 686 | M6: 1371 | N6: 33 | O6: 8 | P6: 23 | Q6: Element={Element$0}Array={Array$0}i2e={Array$0->0->Element$0 | R6: Array$0->1->Element$0 | S6: Array$0->2->Element$0 | T6: Array$0->3->Element$0 | U6: Array$0->4->Element$0 | V6: Array$0->5->Element$0 | W6: Array$0->6->Element$0}length={Array$0->7}
A7: array | B7: array-l31-c21.result.json | C7: 4 | D7: 4 | E7: 2 | F7: 2 | G7: 2 | H7: 2 | I7: 2 | J7: 2 | K7: 115 | L7: 789 | M7: 1532 | N7: 34 | O7: 7 | P7: 25 | Q7: Element={Element$0}Array={Array$0}i2e={Array$0->0->Element$0}length={Array$0->1}
A8: array | B8: array-l31-c42.result.json | C8: 5 | D8: 5 | E8: 2 | F8: 2 | G8: 2 | H8: 2 | I8: 2 | J8: 3 | K8: 99 | L8: 773 | M8: 1569 | N8: 21 | O8: 6 | P8: 14 | Q8: Element={Element$0}Array={Array$0}i2e={Array$0->0->Element$0 | R8: Array$0->4->Element$0}length={Array$0->5}
A9: array | B9: array-l7-c14.result.json | C9: 2 | D9: 2 | E9: 2 | F9: 1 | G9: 1 | H9: 2 | I9: 1 | J9: 1 | K9: 67 | L9: 586 | M9: 1081 | N9: 28 | O9: 12 | P9: 13 | Q9: Array={Array$0}length={Array$0->0}
A10: bempl | B10: bempl-l16-c13.result.json | C10: 4 | D10: 5 | E10: 6 | F10: 6 | G10: 12 | H10: 3 | I10: 3 | J10: 5 | K10: 62 | L10: 583 | M10: 948 | N10: 50 | O10: 6 | P10: 42 | Q10: Room={secure_lab$0 | R10: Room$0}secure_lab={secure_lab$0}Person={Researcher$0 | S10: Employee$0 | T10: Researcher$1}owns={Researcher$0->Key$0 | U10: Researcher$0->Key$1 | V10: Researcher$1->Key$0 | W10: Researcher$1->Key$1}Employee={Employee$0}Researcher={Researcher$0 | X10: Researcher$1}Key={Key$0 | Y10: Key$1 | Z10: Key$2}authorized={Key$0->Employee$0 | AA10: Key$1->Employee$0 | AB10: Key$2->Employee$0}opened_by={Key$0->Room$0 | AC10: Key$1->Room$0 | AD10: Key$2->secure_lab$0}
A11: bempl | B11: bempl-l16-c6.result.json | C11: 5 | D11: 5 | E11: 6 | F11: 6 | G11: 12 | H11: 3 | I11: 3 | J11: 5 | K11: 98 | L11: 778 | M11: 1187 | N11: 109 | O11: 11 | P11: 94 | Q11: Room={secure_lab$0 | R11: Room$0}secure_lab={secure_lab$0}Person={Researcher$0 | S11: Employee$0 | T11: Researcher$1}owns={Researcher$0->Key$0 | U11: Researcher$0->Key$1 | V11: Researcher$1->Key$0 | W11: Researcher$1->Key$1}Employee={Employee$0}Researcher={Researcher$0 | X11: Researcher$1}Key={Key$0 | Y11: Key$1 | Z11: Key$2}authorized={Key$0->Employee$0 | AA11: Key$1->Employee$0 | AB11: Key$2->Employee$0}opened_by={Key$0->Room$0 | AC11: Key$1->Room$0 | AD11: Key$2->secure_lab$0}
A12: bempl | B12: bempl-l16-c8.result.json | C12: 4 | D12: 4 | E12: 6 | F12: 6 | G12: 12 | H12: 3 | I12: 3 | J12: 5 | K12: 56 | L12: 563 | M12: 885 | N12: 44 | O12: 9 | P12: 34 | Q12: Room={secure_lab$0 | R12: Room$0}secure_lab={secure_lab$0}Person={Researcher$0 | S12: Employee$0 | T12: Researcher$1}owns={Researcher$0->Key$0 | U12: Researcher$0->Key$1 | V12: Researcher$1->Key$0 | W12: Researcher$1->Key$1}Employee={Employee$0}Researcher={Researcher$0 | X12: Researcher$1}Key={Key$0 | Y12: Key$1 | Z12: Key$2}authorized={Key$0->Employee$0 | AA12: Key$1->Employee$0 | AB12: Key$2->Employee$0}opened_by={Key$0->Room$0 | AC12: Key$1->Room$0 | AD12: Key$2->secure_lab$0}
A13: bempl | B13: bempl-l2-c27.result.json | C13: 5 | D13: 5 | E13: 6 | F13: 6 | G13: 10 | H13: 3 | I13: 3 | J13: 5 | K13: 38 | L13: 392 | M13: 621 | N13: 84 | O13: 7 | P13: 75 | Q13: Room={secure_lab$0 | R13: Room$0}secure_lab={secure_lab$0}Person={Researcher$0 | S13: Employee$0}owns={Researcher$0->Key$0 | T13: Researcher$0->Key$1}Employee={Employee$0}Researcher={Researcher$0}Key={Key$0 | U13: Key$1 | V13: Key$2}authorized={Key$0->Employee$0 | W13: Key$1->Employee$0 | X13: Key$2->Employee$0}opened_by={Key$0->Room$0 | Y13: Key$1->Room$0 | Z13: Key$2->secure_lab$0}
A14: bempl | B14: bempl-l20-c14.result.json | C14: 5 | D14: 5 | E14: 6 | F14: 6 | G14: 12 | H14: 3 | I14: 3 | J14: 5 | K14: 74 | L14: 704 | M14: 1101 | N14: 55 | O14: 9 | P14: 44 | Q14: Room={secure_lab$0 | R14: Room$0}secure_lab={secure_lab$0}Person={Researcher$0 | S14: Employee$0 | T14: Researcher$1}owns={Researcher$0->Key$1 | U14: Researcher$1->Key$0 | V14: Researcher$1->Key$1}Employee={Employee$0}Researcher={Researcher$0 | W14: Researcher$1}Key={Key$0 | X14: Key$1 | Y14: Key$2}authorized={Key$0->Employee$0 | Z14: Key$1->Employee$0 | AA14: Key$2->Employee$0}opened_by={Key$0->Room$0 | AB14: Key$1->Room$0 | AC14: Key$2->secure_lab$0}
A15: bempl | B15: bempl-l25-c56.result.json | C15: 5 | D15: 5 | E15: 6 | F15: 6 | G15: 12 | H15: 3 | I15: 3 | J15: 5 | K15: 98 | L15: 778 | M15: 1187 | N15: 56 | O15: 5 | P15: 47 | Q15: Room={secure_lab$0 | R15: Room$0}secure_lab={secure_lab$0}Person={Researcher$0 | S15: Employee$0 | T15: Researcher$1}owns={Researcher$0->Key$0 | U15: Researcher$0->Key$1 | V15: Researcher$1->Key$0 | W15: Researcher$1->Key$1}Employee={Employee$0}Researcher={Researcher$0 | X15: Researcher$1}Key={Key$0 | Y15: Key$1 | Z15: Key$2}authorized={Key$0->Employee$0 | AA15: Key$1->Employee$0 | AB15: Key$2->Employee$0}opened_by={Key$0->Room$0 | AC15: Key$1->Room$0 | AD15: Key$2->secure_lab$0}
A16: bempl | B16: bempl-l7-c21.result.json | C16: 5 | D16: 5 | E16: 6 | F16: 6 | G16: 10 | H16: 3 | I16: 3 | J16: 5 | K16: 38 | L16: 392 | M16: 621 | N16: 68 | O16: 5 | P16: 60 | Q16: Room={secure_lab$0 | R16: Room$0}secure_lab={secure_lab$0}Person={Researcher$0 | S16: Employee$0}owns={Researcher$0->Key$0 | T16: Researcher$0->Key$1}Employee={Employee$0}Researcher={Researcher$0}Key={Key$0 | U16: Key$1 | V16: Key$2}authorized={Key$0->Employee$0 | W16: Key$1->Employee$0 | X16: Key$2->Employee$0}opened_by={Key$0->Room$0 | Y16: Key$1->Room$0 | Z16: Key$2->secure_lab$0}
A17: bempl | B17: bempl-l8-c23.result.json | C17: 5 | D17: 5 | E17: 6 | F17: 6 | G17: 10 | H17: 3 | I17: 3 | J17: 5 | K17: 38 | L17: 378 | M17: 596 | N17: 83 | O17: 7 | P17: 75 | Q17: Room={secure_lab$0 | R17: Room$0}secure_lab={secure_lab$0}Person={Researcher$0 | S17: Employee$0}owns={Researcher$0->Key$0 | T17: Researcher$0->Key$1}Employee={Employee$0}Researcher={Researcher$0}Key={Key$0 | U17: Key$1 | V17: Key$2}authorized={Key$0->Employee$0 | W17: Key$1->Employee$0 | X17: Key$2->Employee$0}opened_by={Key$0->Room$0 | Y17: Key$1->Room$0 | Z17: Key$2->secure_lab$0}
A18: binary-tree | B18: binary-tree-l11-c25.result.json | C18: 5 | D18: 5 | E18: 1 | F18: 1 | G18: 3 | H18: 2 | I18: 2 | J18: 4 | K18: 51 | L18: 724 | M18: 1407 | N18: 98 | O18: 8 | P18: 87 | Q18: Node={Node$0 | R18: Node$1 | S18: Node$2}left={Node$0->Node$1 | T18: Node$1->Node$2}right={Node$0->Node$1 | U18: Node$2->Node$0}
A19: binary-tree | B19: binary-tree-l11-c34.result.json | C19: 4 | D19: 5 | E19: 1 | F19: 1 | G19: 2 | H19: 2 | I19: 2 | J19: 2 | K19: 33 | L19: 330 | M19: 525 | N19: 34 | O19: 7 | P19: 21 | Q19: Node={Node$0 | R19: Node$1}left={Node$0->Node$0 | S19: Node$1->Node$0}right={Node$0->Node$1 | T19: Node$1->Node$1}
A20: binary-tree | B20: binary-tree-l15-c24.result.json | C20: 5 | D20: 5 | E20: 1 | F20: 1 | G20: 3 | H20: 2 | I20: 2 | J20: 4 | K20: 51 | L20: 724 | M20: 1407 | N20: 52 | O20: 4 | P20: 44 | Q20: Node={Node$0 | R20: Node$1 | S20: Node$2}left={Node$0->Node$1 | T20: Node$2->Node$0}right={Node$0->Node$2 | U20: Node$1->Node$0 | V20: Node$2->Node$2}
A21: binary-tree | B21: binary-tree-l15-c33.result.json | C21: 5 | D21: 5 | E21: 1 | F21: 1 | G21: 2 | H21: 2 | I21: 2 | J21: 2 | K21: 51 | L21: 484 | M21: 808 | N21: 71 | O21: 6 | P21: 58 | Q21: Node={Node$0 | R21: Node$1}left={Node$0->Node$0 | S21: Node$1->Node$0}right={Node$1->Node$0}
A22: binary-tree | B22: binary-tree-l19-c22.result.json | C22: 5 | D22: 5 | E22: 1 | F22: 1 | G22: 3 | H22: 2 | I22: 2 | J22: 4 | K22: 51 | L22: 724 | M22: 1407 | N22: 47 | O22: 4 | P22: 40 | Q22: Node={Node$0 | R22: Node$1 | S22: Node$2}left={Node$0->Node$1 | T22: Node$1->Node$0 | U22: Node$2->Node$1}right={Node$0->Node$1 | V22: Node$1->Node$2 | W22: Node$2->Node$2}
A23: binary-tree | B23: binary-tree-l19-c29.result.json | C23: 3 | D23: 5 | E23: 1 | F23: 1 | G23: 2 | H23: 2 | I23: 2 | J23: 2 | K23: 51 | L23: 610 | M23: 1136 | N23: 91 | O23: 6 | P23: 70 | Q23: Node={Node$0 | R23: Node$1}left={Node$0->Node$1}right={Node$1->Node$1}
A24: binary-tree | B24: binary-tree-l19-c31.result.json | C24: 5 | D24: 5 | E24: 1 | F24: 1 | G24: 3 | H24: 2 | I24: 2 | J24: 4 | K24: 51 | L24: 724 | M24: 1407 | N24: 41 | O24: 4 | P24: 35 | Q24: Node={Node$0 | R24: Node$1 | S24: Node$2}left={Node$0->Node$2 | T24: Node$1->Node$0 | U24: Node$2->Node$0}right={Node$0->Node$2 | V24: Node$2->Node$0}
A25: binary-tree | B25: binary-tree-l7-c24.result.json | C25: 5 | D25: 5 | E25: 1 | F25: 1 | G25: 3 | H25: 2 | I25: 2 | J25: 4 | K25: 51 | L25: 724 | M25: 1407 | N25: 41 | O25: 4 | P25: 34 | Q25: Node={Node$0 | R25: Node$1 | S25: Node$2}left={Node$1->Node$2 | T25: Node$2->Node$0}right={Node$0->Node$2 | U25: Node$2->Node$0}
A26: binary-tree | B26: binary-tree-l7-c39.result.json | C26: 5 | D26: 5 | E26: 1 | F26: 1 | G26: 3 | H26: 2 | I26: 2 | J26: 4 | K26: 51 | L26: 724 | M26: 1407 | N26: 39 | O26: 4 | P26: 32 | Q26: Node={Node$0 | R26: Node$1 | S26: Node$2}left={Node$0->Node$1 | T26: Node$2->Node$0}right={Node$0->Node$2 | U26: Node$2->Node$0}
A27: class-diagram | B27: class-diagram-l14-c25.result.json | C27: 5 | D27: 5 | E27: 2 | F27: 2 | G27: 4 | H27: 1 | I27: 1 | J27: 3 | K27: 29 | L27: 289 | M27: 543 | N27: 59 | O27: 7 | P27: 50 | Q27: Class={Object$0 | R27: Class$0 | S27: Class$1}ext={Object$0->Class$1 | T27: Class$0->Object$0 | U27: Class$1->Class$0}Object={Object$0}
A28: class-diagram | B28: class-diagram-l19-c17.result.json | C28: 2 | D28: 2 | E28: 2 | F28: 2 | G28: 3 | H28: 1 | I28: 1 | J28: 1 | K28: 14 | L28: 90 | M28: 125 | N28: 14 | O28: 6 | P28: 6 | Q28: Class={Object$0 | R28: Class$0}ext={Object$0->Class$0 | S28: Class$0->Class$0}Object={Object$0}
A29: class-diagram | B29: class-diagram-l19-c31.result.json | C29: 4 | D29: 5 | E29: 2 | F29: 2 | G29: 4 | H29: 1 | I29: 1 | J29: 1 | K29: 41 | L29: 346 | M29: 595 | N29: 71 | O29: 7 | P29: 60 | Q29: Class={Object$0 | R29: Class$0 | S29: Class$1}ext={Class$0->Class$0}Object={Object$0}
A30: class-diagram | B30: class-diagram-l19-c38.result.json | C30: 5 | D30: 5 | E30: 2 | F30: 2 | G30: 4 | H30: 1 | I30: 1 | J30: 2 | K30: 29 | L30: 289 | M30: 549 | N30: 46 | O30: 7 | P30: 38 | Q30: Class={Object$0 | R30: Class$0 | S30: Class$1}ext={Object$0->Class$1 | T30: Class$0->Object$0}Object={Object$0}
A31: class-diagram | B31: class-diagram-l5-c23.result.json | C31: 1 | D31: 1 | E31: 2 | F31: 2 | G31: 3 | H31: 1 | I31: 1 | J31: 1 | K31: 11 | L31: 72 | M31: 98 | N31: 7 | O31: 6 | P31: 0 | Q31: Class={Object$0 | R31: Class$0}ext={Object$0->Class$0 | S31: Class$0->Class$0}Object={Object$0}
A32: class-diagram | B32: class-diagram-l9-c12.result.json | C32: 5 | D32: 5 | E32: 2 | F32: 2 | G32: 4 | H32: 1 | I32: 1 | J32: 2 | K32: 11 | L32: 190 | M32: 402 | N32: 48 | O32: 6 | P32: 40 | Q32: Class={Object$0 | R32: Class$0 | S32: Class$1}ext={Object$0->Class$1 | T32: Class$0->Class$1 | U32: Class$1->Class$0}Object={Object$0}
A33: classroom | B33: classroom-l10-c21.result.json | C33: 5 | D33: 5 | E33: 5 | F33: 5 | G33: 10 | H33: 3 | I33: 3 | J33: 7 | K33: 60 | L33: 623 | M33: 1017 | N33: 123 | O33: 10 | P33: 112 | Q33: Person={Person$0 | R33: Person$1}Tutors={Person$0->Person$0 | S33: Person$1->Person$0}Teaches={Person$0->Class$0 | T33: Person$0->Class$1 | U33: Person$0->Class$2}Group={Group$0 | V33: Group$1 | W33: Group$2}Class={Class$0 | X33: Class$1 | Y33: Class$2}Groups={Class$0->Person$0->Group$0 | Z33: Class$0->Person$0->Group$1 | AA33: Class$0->Person$0->Group$2 | AB33: Class$1->Person$0->Group$0 | AC33: Class$1->Person$0->Group$1 | AD33: Class$1->Person$0->Group$2 | AE33: Class$2->Person$0->Group$0 | AF33: Class$2->Person$0->Group$1 | AG33: Class$2->Person$0->Group$2}Teacher={Person$0}Student={Person$1}
A34: classroom | B34: classroom-l13-c15.result.json | C34: 4 | D34: 4 | E34: 5 | F34: 5 | G34: 10 | H34: 3 | I34: 3 | J34: 7 | K34: 60 | L34: 606 | M34: 980 | N34: 50 | O34: 12 | P34: 36 | Q34: Person={Person$0 | R34: Person$1}Tutors={Person$0->Person$0 | S34: Person$1->Person$0}Teaches={Person$0->Class$0 | T34: Person$0->Class$1 | U34: Person$0->Class$2}Group={Group$0 | V34: Group$1 | W34: Group$2}Class={Class$0 | X34: Class$1 | Y34: Class$2}Groups={Class$0->Person$0->Group$0 | Z34: Class$0->Person$0->Group$1 | AA34: Class$0->Person$0->Group$2 | AB34: Class$1->Person$0->Group$0 | AC34: Class$1->Person$0->Group$1 | AD34: Class$1->Person$0->Group$2 | AE34: Class$2->Person$0->Group$0 | AF34: Class$2->Person$0->Group$1 | AG34: Class$2->Person$0->Group$2}Teacher={Person$0}Student={Person$1}
A35: classroom | B35: classroom-l15-c15.result.json | C35: 4 | D35: 4 | E35: 5 | F35: 5 | G35: 10 | H35: 3 | I35: 3 | J35: 8 | K35: 60 | L35: 606 | M35: 980 | N35: 46 | O35: 14 | P35: 31 | Q35: Person={Person$0 | R35: Person$1}Tutors={Person$0->Person$0 | S35: Person$0->Person$1}Teaches={Person$0->Class$0 | T35: Person$0->Class$1 | U35: Person$0->Class$2}Group={Group$0 | V35: Group$1 | W35: Group$2}Class={Class$0 | X35: Class$1 | Y35: Class$2}Groups={Class$0->Person$0->Group$0 | Z35: Class$0->Person$0->Group$1 | AA35: Class$0->Person$0->Group$2 | AB35: Class$1->Person$0->Group$0 | AC35: Class$1->Person$0->Group$1 | AD35: Class$1->Person$0->Group$2 | AE35: Class$2->Person$0->Group$0 | AF35: Class$2->Person$0->Group$1 | AG35: Class$2->Person$0->Group$2}Teacher={Person$0}Student={Person$1}
A36: classroom | B36: classroom-l25-c15.result.json | C36: 5 | D36: 5 | E36: 5 | F36: 5 | G36: 10 | H36: 3 | I36: 3 | J36: 7 | K36: 60 | L36: 623 | M36: 1017 | N36: 59 | O36: 4 | P36: 50 | Q36: Person={Person$0 | R36: Person$1}Tutors={Person$0->Person$0 | S36: Person$1->Person$0}Teaches={Person$0->Class$0 | T36: Person$0->Class$1 | U36: Person$0->Class$2}Group={Group$0 | V36: Group$1 | W36: Group$2}Class={Class$0 | X36: Class$1 | Y36: Class$2}Groups={Class$0->Person$0->Group$0 | Z36: Class$0->Person$0->Group$1 | AA36: Class$0->Person$0->Group$2 | AB36: Class$1->Person$0->Group$0 | AC36: Class$1->Person$0->Group$1 | AD36: Class$1->Person$0->Group$2 | AE36: Class$2->Person$0->Group$0 | AF36: Class$2->Person$0->Group$1 | AG36: Class$2->Person$0->Group$2}Teacher={Person$0}Student={Person$1}
A37: classroom | B37: classroom-l29-c12.result.json | C37: 5 | D37: 5 | E37: 5 | F37: 5 | G37: 10 | H37: 3 | I37: 3 | J37: 7 | K37: 60 | L37: 623 | M37: 1017 | N37: 69 | O37: 7 | P37: 56 | Q37: Person={Person$0 | R37: Person$1}Tutors={Person$0->Person$0 | S37: Person$1->Person$0}Teaches={Person$0->Class$0 | T37: Person$0->Class$1 | U37: Person$0->Class$2}Group={Group$0 | V37: Group$1 | W37: Group$2}Class={Class$0 | X37: Class$1 | Y37: Class$2}Groups={Class$0->Person$0->Group$0 | Z37: Class$0->Person$0->Group$1 | AA37: Class$0->Person$0->Group$2 | AB37: Class$1->Person$0->Group$0 | AC37: Class$1->Person$0->Group$1 | AD37: Class$1->Person$0->Group$2 | AE37: Class$2->Person$0->Group$0 | AF37: Class$2->Person$0->Group$1 | AG37: Class$2->Person$0->Group$2}Teacher={Person$0}Student={Person$1}
A38: classroom | B38: classroom-l29-c22.result.json | C38: 5 | D38: 5 | E38: 5 | F38: 5 | G38: 10 | H38: 3 | I38: 3 | J38: 8 | K38: 60 | L38: 623 | M38: 1017 | N38: 67 | O38: 4 | P38: 57 | Q38: Person={Person$0 | R38: Person$1}Tutors={Person$0->Person$0 | S38: Person$0->Person$1}Teaches={Person$0->Class$0 | T38: Person$0->Class$1 | U38: Person$0->Class$2}Group={Group$0 | V38: Group$1 | W38: Group$2}Class={Class$0 | X38: Class$1 | Y38: Class$2}Groups={Class$0->Person$0->Group$0 | Z38: Class$0->Person$0->Group$1 | AA38: Class$0->Person$0->Group$2 | AB38: Class$1->Person$0->Group$0 | AC38: Class$1->Person$0->Group$1 | AD38: Class$1->Person$0->Group$2 | AE38: Class$2->Person$0->Group$0 | AF38: Class$2->Person$0->Group$1 | AG38: Class$2->Person$0->Group$2}Teacher={Person$0}Student={Person$1}
A39: classroom | B39: classroom-l33-c15.result.json | C39: 5 | D39: 5 | E39: 5 | F39: 5 | G39: 10 | H39: 3 | I39: 3 | J39: 10 | K39: 60 | L39: 659 | M39: 1128 | N39: 90 | O39: 10 | P39: 79 | Q39: Person={Person$0 | R39: Person$1}Tutors={Person$0->Person$0 | S39: Person$0->Person$1}Teaches={Person$0->Class$1 | T39: Person$0->Class$2 | U39: Person$1->Class$0}Group={Group$0 | V39: Group$1 | W39: Group$2}Class={Class$0 | X39: Class$1 | Y39: Class$2}Groups={Class$0->Person$0->Group$0 | Z39: Class$0->Person$0->Group$1 | AA39: Class$0->Person$0->Group$2 | AB39: Class$1->Person$0->Group$1 | AC39: Class$1->Person$0->Group$2 | AD39: Class$1->Person$1->Group$0 | AE39: Class$2->Person$0->Group$0 | AF39: Class$2->Person$0->Group$2 | AG39: Class$2->Person$1->Group$1}Teacher={Person$0}Student={Person$1}
A40: classroom | B40: classroom-l37-c25.result.json | C40: 5 | D40: 5 | E40: 5 | F40: 5 | G40: 10 | H40: 3 | I40: 2 | J40: 5 | K40: 90 | L40: 862 | M40: 1462 | N40: 104 | O40: 10 | P40: 92 | Q40: Person={Person$0 | R40: Person$1 | S40: Person$2}Tutors={Person$0->Person$1 | T40: Person$0->Person$2 | U40: Person$2->Person$0}Teaches={Person$0->Class$1 | V40: Person$1->Class$0 | W40: Person$2->Class$0}Group={Group$0}Class={Class$0 | X40: Class$1}Teacher={Person$0 | Y40: Person$1 | Z40: Person$2}Student={Person$0}
...

Sheet 5 target
A1: array | B1: array-l12-c18.result.json | C1: 3 | D1: 4 | E1: 2 | F1: 1 | G1: 1 | H1: 2 | I1: 1 | J1: 1 | K1: 67 | L1: 620 | M1: 1328 | N1: 218 | O1: 22 | P1: 184 | Q1: Array={Array$0}length={Array$0->0}
A2: array | B2: array-l18-c8.result.json | C2: 3 | D2: 4 | E2: 2 | F2: 1 | G2: 1 | H2: 2 | I2: 1 | J2: 1 | K2: 67 | L2: 620 | M2: 1328 | N2: 54 | O2: 10 | P2: 38 | Q2: Array={Array$0}length={Array$0->0}
A3: array | B3: array-l24-c17.result.json | C3: 4 | D3: 4 | E3: 2 | F3: 2 | G3: 2 | H3: 2 | I3: 2 | J3: 2 | K3: 83 | L3: 686 | M3: 1438 | N3: 69 | O3: 16 | P3: 47 | Q3: Element={Element$0}Array={Array$0}i2e={Array$0->0->Element$0}length={Array$0->1}
A4: array | B4: array-l24-c21.result.json | C4: 4 | D4: 4 | E4: 2 | F4: 2 | G4: 2 | H4: 2 | I4: 2 | J4: 2 | K4: 115 | L4: 789 | M4: 1599 | N4: 61 | O4: 14 | P4: 41 | Q4: Element={Element$0}Array={Array$0}i2e={Array$0->0->Element$0}length={Array$0->2}
A5: array | B5: array-l24-c55.result.json | C5: 5 | D5: 5 | E5: 2 | F5: 2 | G5: 2 | H5: 2 | I5: 2 | J5: 2 | K5: 99 | L5: 773 | M5: 1636 | N5: 40 | O5: 13 | P5: 21 | Q5: Element={Element$0}Array={Array$0}i2e={Array$0->0->Element$0}length={Array$0->1}
A6: array | B6: array-l31-c17.result.json | C6: 4 | D6: 4 | E6: 2 | F6: 2 | G6: 2 | H6: 2 | I6: 2 | J6: 2 | K6: 83 | L6: 686 | M6: 1438 | N6: 38 | O6: 11 | P6: 23 | Q6: Element={Element$0}Array={Array$0}i2e={Array$0->0->Element$0}length={Array$0->1}
A7: array | B7: array-l31-c21.result.json | C7: 4 | D7: 4 | E7: 2 | F7: 2 | G7: 2 | H7: 2 | I7: 2 | J7: 2 | K7: 115 | L7: 789 | M7: 1599 | N7: 39 | O7: 9 | P7: 26 | Q7: Element={Element$0}Array={Array$0}i2e={Array$0->0->Element$0}length={Array$0->1}
A8: array | B8: array-l31-c42.result.json | C8: 5 | D8: 5 | E8: 2 | F8: 2 | G8: 2 | H8: 2 | I8: 2 | J8: 2 | K8: 99 | L8: 773 | M8: 1636 | N8: 25 | O8: 8 | P8: 15 | Q8: Element={Element$0}Array={Array$0}i2e={Array$0->0->Element$0}length={Array$0->1}
A9: array | B9: array-l7-c14.result.json | C9: 2 | D9: 2 | E9: 2 | F9: 1 | G9: 1 | H9: 2 | I9: 1 | J9: 1 | K9: 67 | L9: 586 | M9: 1148 | N9: 28 | O9: 11 | P9: 14 | Q9: Array={Array$0}length={Array$0->0}
A10: bempl | B10: bempl-l16-c13.result.json | C10: 4 | D10: 5 | E10: 6 | F10: 5 | G10: 6 | H10: 3 | I10: 2 | J10: 2 | K10: 62 | L10: 583 | M10: 986 | N10: 52 | O10: 7 | P10: 40 | Q10: Room={secure_lab$0 | R10: Room$0}secure_lab={secure_lab$0}Person={Employee$0}Employee={Employee$0}Key={Key$0}authorized={Key$0->Employee$0}opened_by={Key$0->secure_lab$0}
A11: bempl | B11: bempl-l16-c6.result.json | C11: 5 | D11: 5 | E11: 6 | F11: 5 | G11: 6 | H11: 3 | I11: 0 | J11: 0 | K11: 98 | L11: 778 | M11: 1225 | N11: 102 | O11: 10 | P11: 87 | Q11: Room={secure_lab$0}secure_lab={secure_lab$0}Person={Researcher$0 | R11: Employee$0}Employee={Employee$0}Researcher={Researcher$0}
A12: bempl | B12: bempl-l16-c8.result.json | C12: 4 | D12: 4 | E12: 6 | F12: 6 | G12: 7 | H12: 3 | I12: 3 | J12: 3 | K12: 56 | L12: 563 | M12: 923 | N12: 50 | O12: 9 | P12: 38 | Q12: Room={secure_lab$0}secure_lab={secure_lab$0}Person={Employee$0 | R12: Researcher$0}owns={Researcher$0->Key$0}Employee={Employee$0}Researcher={Researcher$0}Key={Key$0}authorized={Key$0->Employee$0}opened_by={Key$0->secure_lab$0}
A13: bempl | B13: bempl-l2-c27.result.json | C13: 5 | D13: 5 | E13: 6 | F13: 5 | G13: 6 | H13: 3 | I13: 0 | J13: 0 | K13: 38 | L13: 392 | M13: 659 | N13: 81 | O13: 7 | P13: 71 | Q13: Room={secure_lab$0}secure_lab={secure_lab$0}Person={Researcher$0 | R13: Employee$0}Employee={Employee$0}Researcher={Researcher$0}
A14: bempl | B14: bempl-l20-c14.result.json | C14: 5 | D14: 5 | E14: 6 | F14: 6 | G14: 7 | H14: 3 | I14: 3 | J14: 3 | K14: 74 | L14: 704 | M14: 1139 | N14: 50 | O14: 9 | P14: 38 | Q14: Room={secure_lab$0}secure_lab={secure_lab$0}Person={Researcher$0 | R14: Employee$0}owns={Researcher$0->Key$0}Employee={Employee$0}Researcher={Researcher$0}Key={Key$0}authorized={Key$0->Employee$0}opened_by={Key$0->secure_lab$0}
A15: bempl | B15: bempl-l25-c56.result.json | C15: 5 | D15: 5 | E15: 6 | F15: 5 | G15: 6 | H15: 3 | I15: 0 | J15: 0 | K15: 98 | L15: 778 | M15: 1225 | N15: 66 | O15: 6 | P15: 54 | Q15: Room={secure_lab$0}secure_lab={secure_lab$0}Person={Researcher$0 | R15: Employee$0}Employee={Employee$0}Researcher={Researcher$0}
A16: bempl | B16: bempl-l7-c21.result.json | C16: 5 | D16: 5 | E16: 6 | F16: 5 | G16: 6 | H16: 3 | I16: 0 | J16: 0 | K16: 38 | L16: 392 | M16: 659 | N16: 62 | O16: 5 | P16: 55 | Q16: Room={secure_lab$0}secure_lab={secure_lab$0}Person={Researcher$0 | R16: Employee$0}Employee={Employee$0}Researcher={Researcher$0}
A17: bempl | B17: bempl-l8-c23.result.json | C17: 5 | D17: 5 | E17: 6 | F17: 5 | G17: 7 | H17: 3 | I17: 0 | J17: 0 | K17: 38 | L17: 378 | M17: 634 | N17: 72 | O17: 9 | P17: 61 | Q17: Room={secure_lab$0 | R17: Room$0}secure_lab={secure_lab$0}Person={Researcher$0 | S17: Employee$0}Employee={Employee$0}Researcher={Researcher$0}
A18: binary-tree | B18: binary-tree-l11-c25.result.json | C18: 5 | D18: 5 | E18: 1 | F18: 1 | G18: 3 | H18: 2 | I18: 2 | J18: 4 | K18: 51 | L18: 724 | M18: 1428 | N18: 90 | O18: 12 | P18: 74 | Q18: Node={Node$0 | R18: Node$1 | S18: Node$2}left={Node$1->Node$0 | T18: Node$2->Node$1}right={Node$0->Node$2 | U18: Node$2->Node$1}
A19: binary-tree | B19: binary-tree-l11-c34.result.json | C19: 4 | D19: 5 | E19: 1 | F19: 1 | G19: 2 | H19: 2 | I19: 1 | J19: 1 | K19: 33 | L19: 330 | M19: 546 | N19: 35 | O19: 7 | P19: 20 | Q19: Node={Node$0 | R19: Node$1}left={Node$1->Node$0}
A20: binary-tree | B20: binary-tree-l15-c24.result.json | C20: 5 | D20: 5 | E20: 1 | F20: 1 | G20: 3 | H20: 2 | I20: 2 | J20: 4 | K20: 51 | L20: 724 | M20: 1428 | N20: 49 | O20: 6 | P20: 40 | Q20: Node={Node$0 | R20: Node$1 | S20: Node$2}left={Node$1->Node$0 | T20: Node$2->Node$1}right={Node$0->Node$2 | U20: Node$2->Node$1}
A21: binary-tree | B21: binary-tree-l15-c33.result.json | C21: 5 | D21: 5 | E21: 1 | F21: 1 | G21: 2 | H21: 2 | I21: 2 | J21: 2 | K21: 51 | L21: 484 | M21: 829 | N21: 84 | O21: 8 | P21: 67 | Q21: Node={Node$0 | R21: Node$1}left={Node$0->Node$0 | S21: Node$1->Node$0}right={Node$1->Node$0}
A22: binary-tree | B22: binary-tree-l19-c22.result.json | C22: 5 | D22: 5 | E22: 1 | F22: 1 | G22: 3 | H22: 2 | I22: 2 | J22: 4 | K22: 51 | L22: 724 | M22: 1428 | N22: 44 | O22: 5 | P22: 35 | Q22: Node={Node$0 | R22: Node$1 | S22: Node$2}left={Node$0->Node$2 | T22: Node$2->Node$1}right={Node$1->Node$2 | U22: Node$2->Node$1}
A23: binary-tree | B23: binary-tree-l19-c29.result.json | C23: 3 | D23: 5 | E23: 1 | F23: 1 | G23: 2 | H23: 2 | I23: 1 | J23: 1 | K23: 51 | L23: 610 | M23: 1157 | N23: 85 | O23: 6 | P23: 63 | Q23: Node={Node$0 | R23: Node$1}left={Node$1->Node$1}
A24: binary-tree | B24: binary-tree-l19-c31.result.json | C24: 5 | D24: 5 | E24: 1 | F24: 1 | G24: 3 | H24: 2 | I24: 2 | J24: 4 | K24: 51 | L24: 724 | M24: 1428 | N24: 48 | O24: 8 | P24: 37 | Q24: Node={Node$0 | R24: Node$1 | S24: Node$2}left={Node$0->Node$1 | T24: Node$1->Node$2}right={Node$0->Node$1 | U24: Node$2->Node$0}
A25: binary-tree | B25: binary-tree-l7-c24.result.json | C25: 5 | D25: 5 | E25: 1 | F25: 1 | G25: 3 | H25: 2 | I25: 2 | J25: 4 | K25: 51 | L25: 724 | M25: 1428 | N25: 44 | O25: 6 | P25: 35 | Q25: Node={Node$0 | R25: Node$1 | S25: Node$2}left={Node$0->Node$1 | T25: Node$1->Node$2}right={Node$0->Node$2 | U25: Node$2->Node$1}
A26: binary-tree | B26: binary-tree-l7-c39.result.json | C26: 5 | D26: 5 | E26: 1 | F26: 1 | G26: 3 | H26: 2 | I26: 2 | J26: 4 | K26: 51 | L26: 724 | M26: 1428 | N26: 43 | O26: 5 | P26: 35 | Q26: Node={Node$0 | R26: Node$1 | S26: Node$2}left={Node$1->Node$0 | T26: Node$2->Node$1}right={Node$1->Node$2 | U26: Node$2->Node$1}
A27: class-diagram | B27: class-diagram-l14-c25.result.json | C27: 5 | D27: 5 | E27: 2 | F27: 2 | G27: 4 | H27: 1 | I27: 1 | J27: 2 | K27: 29 | L27: 289 | M27: 554 | N27: 58 | O27: 8 | P27: 48 | Q27: Class={Object$0 | R27: Class$0 | S27: Class$1}ext={Object$0->Class$1 | T27: Class$1->Class$0}Object={Object$0}
A28: class-diagram | B28: class-diagram-l19-c17.result.json | C28: 2 | D28: 2 | E28: 2 | F28: 2 | G28: 3 | H28: 1 | I28: 0 | J28: 0 | K28: 14 | L28: 90 | M28: 136 | N28: 16 | O28: 7 | P28: 7 | Q28: Class={Object$0 | R28: Class$0}Object={Object$0}
A29: class-diagram | B29: class-diagram-l19-c31.result.json | C29: 4 | D29: 5 | E29: 2 | F29: 2 | G29: 4 | H29: 1 | I29: 1 | J29: 1 | K29: 41 | L29: 346 | M29: 606 | N29: 77 | O29: 8 | P29: 65 | Q29: Class={Object$0 | R29: Class$0 | S29: Class$1}ext={Class$1->Class$0}Object={Object$0}
A30: class-diagram | B30: class-diagram-l19-c38.result.json | C30: 5 | D30: 5 | E30: 2 | F30: 2 | G30: 4 | H30: 1 | I30: 1 | J30: 2 | K30: 29 | L30: 289 | M30: 560 | N30: 53 | O30: 7 | P30: 43 | Q30: Class={Object$0 | R30: Class$0 | S30: Class$1}ext={Object$0->Class$1 | T30: Class$1->Class$0}Object={Object$0}
A31: class-diagram | B31: class-diagram-l5-c23.result.json | C31: 1 | D31: 1 | E31: 2 | F31: 2 | G31: 2 | H31: 1 | I31: 0 | J31: 0 | K31: 11 | L31: 72 | M31: 109 | N31: 8 | O31: 6 | P31: 0 | Q31: Class={Object$0}Object={Object$0}
A32: class-diagram | B32: class-diagram-l9-c12.result.json | C32: 5 | D32: 5 | E32: 2 | F32: 2 | G32: 4 | H32: 1 | I32: 1 | J32: 2 | K32: 11 | L32: 190 | M32: 413 | N32: 51 | O32: 7 | P32: 42 | Q32: Class={Object$0 | R32: Class$0 | S32: Class$1}ext={Class$0->Class$1 | T32: Class$1->Object$0}Object={Object$0}
A33: classroom | B33: classroom-l10-c21.result.json | C33: 5 | D33: 5 | E33: 5 | F33: 4 | G33: 5 | H33: 3 | I33: 0 | J33: 0 | K33: 60 | L33: 623 | M33: 1077 | N33: 121 | O33: 9 | P33: 110 | Q33: Person={Person$0 | R33: Person$1}Group={Group$0}Class={Class$0}Teacher={Person$1}
A34: classroom | B34: classroom-l13-c15.result.json | C34: 4 | D34: 4 | E34: 5 | F34: 3 | G34: 3 | H34: 3 | I34: 0 | J34: 0 | K34: 60 | L34: 606 | M34: 1040 | N34: 45 | O34: 12 | P34: 31 | Q34: Person={Person$0}Group={Group$0}Class={Class$0}
A35: classroom | B35: classroom-l15-c15.result.json | C35: 4 | D35: 4 | E35: 5 | F35: 3 | G35: 3 | H35: 3 | I35: 0 | J35: 0 | K35: 60 | L35: 606 | M35: 1040 | N35: 43 | O35: 11 | P35: 30 | Q35: Person={Person$0}Group={Group$0}Class={Class$0}
A36: classroom | B36: classroom-l25-c15.result.json | C36: 5 | D36: 5 | E36: 5 | F36: 4 | G36: 5 | H36: 3 | I36: 0 | J36: 0 | K36: 60 | L36: 623 | M36: 1077 | N36: 61 | O36: 5 | P36: 50 | Q36: Person={Person$0 | R36: Person$1}Group={Group$0}Class={Class$0}Teacher={Person$1}
A37: classroom | B37: classroom-l29-c12.result.json | C37: 5 | D37: 5 | E37: 5 | F37: 4 | G37: 5 | H37: 3 | I37: 0 | J37: 0 | K37: 60 | L37: 623 | M37: 1077 | N37: 68 | O37: 5 | P37: 56 | Q37: Person={Person$0 | R37: Person$1}Group={Group$0}Class={Class$0}Teacher={Person$1}
A38: classroom | B38: classroom-l29-c22.result.json | C38: 5 | D38: 5 | E38: 5 | F38: 4 | G38: 5 | H38: 3 | I38: 0 | J38: 0 | K38: 60 | L38: 623 | M38: 1077 | N38: 62 | O38: 4 | P38: 52 | Q38: Person={Person$0 | R38: Person$1}Group={Group$0}Class={Class$0}Student={Person$1}
A39: classroom | B39: classroom-l33-c15.result.json | C39: 5 | D39: 5 | E39: 5 | F39: 2 | G39: 3 | H39: 3 | I39: 2 | J39: 2 | K39: 60 | L39: 659 | M39: 1188 | N39: 82 | O39: 10 | P39: 70 | Q39: Person={Person$0 | R39: Person$1}Tutors={Person$0->Person$1}Teaches={Person$1->Class$0}Class={Class$0}
A40: classroom | B40: classroom-l37-c25.result.json | C40: 5 | D40: 5 | E40: 5 | F40: 2 | G40: 4 | H40: 3 | I40: 1 | J40: 2 | K40: 90 | L40: 862 | M40: 1522 | N40: 105 | O40: 10 | P40: 93 | Q40: Person={Person$0 | R40: Person$1 | S40: Person$2}Tutors={Person$0->Person$2 | T40: Person$1->Person$0}Teacher={Person$2}
...

Sheet 10 base
A1: array | B1: array-l12-c18.result.json | C1: 4 | D1: 4 | E1: 2 | F1: 2 | G1: 2 | H1: 2 | I1: 2 | J1: 8 | K1: 67 | L1: 620 | M1: 1261 | N1: 211 | O1: 14 | P1: 189 | Q1: Element={Element$0}Array={Array$0}i2e={Array$0->0->Element$0 | R1: Array$0->1->Element$0 | S1: Array$0->2->Element$0 | T1: Array$0->3->Element$0 | U1: Array$0->4->Element$0 | V1: Array$0->5->Element$0 | W1: Array$0->6->Element$0}length={Array$0->7}
A2: array | B2: array-l18-c8.result.json | C2: 4 | D2: 4 | E2: 2 | F2: 2 | G2: 2 | H2: 2 | I2: 2 | J2: 8 | K2: 67 | L2: 620 | M2: 1261 | N2: 59 | O2: 10 | P2: 46 | Q2: Element={Element$0}Array={Array$0}i2e={Array$0->0->Element$0 | R2: Array$0->1->Element$0 | S2: Array$0->2->Element$0 | T2: Array$0->3->Element$0 | U2: Array$0->4->Element$0 | V2: Array$0->5->Element$0 | W2: Array$0->6->Element$0}length={Array$0->7}
A3: array | B3: array-l24-c17.result.json | C3: 4 | D3: 4 | E3: 2 | F3: 2 | G3: 2 | H3: 2 | I3: 2 | J3: 2 | K3: 83 | L3: 686 | M3: 1371 | N3: 77 | O3: 16 | P3: 58 | Q3: Element={Element$0}Array={Array$0}i2e={Array$0->0->Element$0}length={Array$0->1}
A4: array | B4: array-l24-c21.result.json | C4: 4 | D4: 4 | E4: 2 | F4: 2 | G4: 2 | H4: 2 | I4: 2 | J4: 2 | K4: 115 | L4: 789 | M4: 1532 | N4: 56 | O4: 13 | P4: 41 | Q4: Element={Element$0}Array={Array$0}i2e={Array$0->6->Element$0}length={Array$0->7}
A5: array | B5: array-l24-c55.result.json | C5: 5 | D5: 5 | E5: 2 | F5: 2 | G5: 2 | H5: 2 | I5: 2 | J5: 6 | K5: 99 | L5: 773 | M5: 1569 | N5: 67 | O5: 11 | P5: 53 | Q5: Element={Element$0}Array={Array$0}i2e={Array$0->0->Element$0 | R5: Array$0->1->Element$0 | S5: Array$0->2->Element$0 | T5: Array$0->3->Element$0 | U5: Array$0->4->Element$0}length={Array$0->5}
A6: array | B6: array-l31-c17.result.json | C6: 4 | D6: 4 | E6: 2 | F6: 2 | G6: 2 | H6: 2 | I6: 2 | J6: 6 | K6: 83 | L6: 686 | M6: 1371 | N6: 33 | O6: 6 | P6: 25 | Q6: Element={Element$0}Array={Array$0}i2e={Array$0->0->Element$0 | R6: Array$0->1->Element$0 | S6: Array$0->2->Element$0 | T6: Array$0->3->Element$0 | U6: Array$0->4->Element$0}length={Array$0->5}
A7: array | B7: array-l31-c21.result.json | C7: 4 | D7: 4 | E7: 2 | F7: 2 | G7: 2 | H7: 2 | I7: 2 | J7: 2 | K7: 115 | L7: 789 | M7: 1532 | N7: 28 | O7: 6 | P7: 20 | Q7: Element={Element$0}Array={Array$0}i2e={Array$0->0->Element$0}length={Array$0->1}
A8: array | B8: array-l31-c42.result.json | C8: 5 | D8: 5 | E8: 2 | F8: 2 | G8: 2 | H8: 2 | I8: 2 | J8: 8 | K8: 99 | L8: 773 | M8: 1569 | N8: 51 | O8: 6 | P8: 43 | Q8: Element={Element$0}Array={Array$0}i2e={Array$0->0->Element$0 | R8: Array$0->1->Element$0 | S8: Array$0->2->Element$0 | T8: Array$0->3->Element$0 | U8: Array$0->4->Element$0 | V8: Array$0->5->Element$0 | W8: Array$0->6->Element$0}length={Array$0->7}
A9: array | B9: array-l7-c14.result.json | C9: 2 | D9: 2 | E9: 2 | F9: 1 | G9: 1 | H9: 2 | I9: 1 | J9: 1 | K9: 67 | L9: 586 | M9: 1081 | N9: 24 | O9: 14 | P9: 7 | Q9: Array={Array$0}length={Array$0->0}
A10: bempl | B10: bempl-l16-c13.result.json | C10: 6 | D10: 7 | E10: 6 | F10: 6 | G10: 12 | H10: 3 | I10: 3 | J10: 5 | K10: 92 | L10: 847 | M10: 1412 | N10: 159 | O10: 10 | P10: 147 | Q10: Room={secure_lab$0 | R10: Room$0}secure_lab={secure_lab$0}Person={Researcher$0 | S10: Employee$0 | T10: Researcher$1}owns={Researcher$0->Key$0 | U10: Researcher$0->Key$1 | V10: Researcher$1->Key$0 | W10: Researcher$1->Key$1}Employee={Employee$0}Researcher={Researcher$0 | X10: Researcher$1}Key={Key$0 | Y10: Key$1 | Z10: Key$2}authorized={Key$0->Employee$0 | AA10: Key$1->Employee$0 | AB10: Key$2->Employee$0}opened_by={Key$0->Room$0 | AC10: Key$1->Room$0 | AD10: Key$2->secure_lab$0}
A11: bempl | B11: bempl-l16-c6.result.json | C11: 7 | D11: 10 | E11: 6 | F11: 6 | G11: 10 | H11: 3 | I11: 3 | J11: 3 | K11: 308 | L11: 2093 | M11: 3236 | N11: 384 | O11: 12 | P11: 366 | Q11: Room={secure_lab$0 | R11: Room$0}secure_lab={secure_lab$0}Person={Researcher$0 | S11: Employee$0 | T11: Researcher$1}owns={Researcher$0->Key$0}Employee={Employee$0}Researcher={Researcher$0 | U11: Researcher$1}Key={Key$0}authorized={Key$0->Employee$0}opened_by={Key$0->Room$0}
A12: bempl | B12: bempl-l16-c8.result.json | C12: 4 | D12: 4 | E12: 6 | F12: 6 | G12: 12 | H12: 3 | I12: 3 | J12: 5 | K12: 56 | L12: 563 | M12: 885 | N12: 36 | O12: 9 | P12: 26 | Q12: Room={secure_lab$0 | R12: Room$0}secure_lab={secure_lab$0}Person={Researcher$0 | S12: Employee$0 | T12: Researcher$1}owns={Researcher$0->Key$0 | U12: Researcher$0->Key$1 | V12: Researcher$1->Key$0 | W12: Researcher$1->Key$1}Employee={Employee$0}Researcher={Researcher$0 | X12: Researcher$1}Key={Key$0 | Y12: Key$1 | Z12: Key$2}authorized={Key$0->Employee$0 | AA12: Key$1->Employee$0 | AB12: Key$2->Employee$0}opened_by={Key$0->Room$0 | AC12: Key$1->Room$0 | AD12: Key$2->secure_lab$0}
A13: bempl | B13: bempl-l2-c27.result.json | C13: 5 | D13: 5 | E13: 6 | F13: 6 | G13: 10 | H13: 3 | I13: 3 | J13: 5 | K13: 38 | L13: 392 | M13: 621 | N13: 72 | O13: 6 | P13: 64 | Q13: Room={secure_lab$0 | R13: Room$0}secure_lab={secure_lab$0}Person={Researcher$0 | S13: Employee$0}owns={Researcher$0->Key$0 | T13: Researcher$0->Key$1}Employee={Employee$0}Researcher={Researcher$0}Key={Key$0 | U13: Key$1 | V13: Key$2}authorized={Key$0->Employee$0 | W13: Key$1->Employee$0 | X13: Key$2->Employee$0}opened_by={Key$0->Room$0 | Y13: Key$1->Room$0 | Z13: Key$2->secure_lab$0}
A14: bempl | B14: bempl-l20-c14.result.json | C14: 8 | D14: 8 | E14: 6 | F14: 6 | G14: 12 | H14: 3 | I14: 3 | J14: 4 | K14: 134 | L14: 1171 | M14: 1995 | N14: 135 | O14: 9 | P14: 124 | Q14: Room={secure_lab$0 | R14: Room$0}secure_lab={secure_lab$0}Person={Researcher$0 | S14: Employee$0 | T14: Researcher$1}owns={Researcher$0->Key$1}Employee={Employee$0}Researcher={Researcher$0 | U14: Researcher$1}Key={Key$0 | V14: Key$1 | W14: Key$2}authorized={Key$0->Employee$0 | X14: Key$1->Employee$0 | Y14: Key$2->Employee$0}opened_by={Key$0->Room$0 | Z14: Key$1->Room$0 | AA14: Key$2->secure_lab$0}
A15: bempl | B15: bempl-l25-c56.result.json | C15: 8 | D15: 10 | E15: 6 | F15: 6 | G15: 13 | H15: 3 | I15: 3 | J15: 3 | K15: 423 | L15: 3088 | M15: 5166 | N15: 262 | O15: 15 | P15: 237 | Q15: Room={secure_lab$0 | R15: Room$0 | S15: Room$1}secure_lab={secure_lab$0}Person={Employee$0 | T15: Researcher$0 | U15: Researcher$1 | V15: Employee$1}owns={Researcher$1->Key$0}Employee={Employee$0 | W15: Employee$1}Researcher={Researcher$0 | X15: Researcher$1}Key={Key$0}authorized={Key$0->Employee$1}opened_by={Key$0->Room$0}
A16: bempl | B16: bempl-l7-c21.result.json | C16: 6 | D16: 6 | E16: 6 | F16: 6 | G16: 10 | H16: 3 | I16: 3 | J16: 5 | K16: 38 | L16: 393 | M16: 623 | N16: 77 | O16: 6 | P16: 70 | Q16: Room={secure_lab$0 | R16: Room$0}secure_lab={secure_lab$0}Person={Researcher$0 | S16: Employee$0}owns={Researcher$0->Key$0 | T16: Researcher$0->Key$1}Employee={Employee$0}Researcher={Researcher$0}Key={Key$0 | U16: Key$1 | V16: Key$2}authorized={Key$0->Employee$0 | W16: Key$1->Employee$0 | X16: Key$2->Employee$0}opened_by={Key$0->Room$0 | Y16: Key$1->Room$0 | Z16: Key$2->secure_lab$0}
A17: bempl | B17: bempl-l8-c23.result.json | C17: 5 | D17: 5 | E17: 6 | F17: 6 | G17: 10 | H17: 3 | I17: 3 | J17: 5 | K17: 38 | L17: 378 | M17: 596 | N17: 46 | O17: 8 | P17: 37 | Q17: Room={secure_lab$0 | R17: Room$0}secure_lab={secure_lab$0}Person={Researcher$0 | S17: Employee$0}owns={Researcher$0->Key$0 | T17: Researcher$0->Key$1}Employee={Employee$0}Researcher={Researcher$0}Key={Key$0 | U17: Key$1 | V17: Key$2}authorized={Key$0->Employee$0 | W17: Key$1->Employee$0 | X17: Key$2->Employee$0}opened_by={Key$0->Room$0 | Y17: Key$1->Room$0 | Z17: Key$2->secure_lab$0}
A18: binary-tree | B18: binary-tree-l11-c25.result.json | C18: 10 | D18: 10 | E18: 1 | F18: 1 | G18: 3 | H18: 2 | I18: 2 | J18: 5 | K18: 129 | L18: 1352 | M18: 2340 | N18: 239 | O18: 10 | P18: 226 | Q18: Node={Node$0 | R18: Node$1 | S18: Node$2}left={Node$0->Node$1 | T18: Node$1->Node$2 | U18: Node$2->Node$0}right={Node$0->Node$1 | V18: Node$1->Node$0 | W18: Node$2->Node$0}
A19: binary-tree | B19: binary-tree-l11-c34.result.json | C19: 9 | D19: 10 | E19: 1 | F19: 1 | G19: 3 | H19: 2 | I19: 2 | J19: 4 | K19: 108 | L19: 1097 | M19: 1892 | N19: 123 | O19: 9 | P19: 107 | Q19: Node={Node$0 | R19: Node$1 | S19: Node$2}left={Node$0->Node$2 | T19: Node$1->Node$0 | U19: Node$2->Node$0}right={Node$0->Node$1 | V19: Node$1->Node$0 | W19: Node$2->Node$0}
A20: binary-tree | B20: binary-tree-l15-c24.result.json | C20: 10 | D20: 10 | E20: 1 | F20: 1 | G20: 3 | H20: 2 | I20: 2 | J20: 4 | K20: 129 | L20: 1352 | M20: 2340 | N20: 127 | O20: 6 | P20: 119 | Q20: Node={Node$0 | R20: Node$1 | S20: Node$2}left={Node$0->Node$1 | T20: Node$1->Node$0 | U20: Node$2->Node$0}right={Node$1->Node$0 | V20: Node$2->Node$1}
A21: binary-tree | B21: binary-tree-l15-c33.result.json | C21: 10 | D21: 10 | E21: 1 | F21: 1 | G21: 3 | H21: 2 | I21: 2 | J21: 4 | K21: 129 | L21: 1260 | M21: 2172 | N21: 159 | O21: 8 | P21: 143 | Q21: Node={Node$0 | R21: Node$1 | S21: Node$2}left={Node$0->Node$1 | T21: Node$2->Node$0}right={Node$0->Node$2 | U21: Node$1->Node$2 | V21: Node$2->Node$1}
A22: binary-tree | B22: binary-tree-l19-c22.result.json | C22: 10 | D22: 10 | E22: 1 | F22: 1 | G22: 3 | H22: 2 | I22: 2 | J22: 4 | K22: 129 | L22: 1352 | M22: 2340 | N22: 122 | O22: 6 | P22: 113 | Q22: Node={Node$0 | R22: Node$1 | S22: Node$2}left={Node$1->Node$0 | T22: Node$2->Node$1}right={Node$0->Node$1 | U22: Node$1->Node$0 | V22: Node$2->Node$0}
A23: binary-tree | B23: binary-tree-l19-c29.result.json | C23: 7 | D23: 10 | E23: 1 | F23: 1 | G23: 3 | H23: 2 | I23: 2 | J23: 3 | K23: 156 | L23: 2167 | M23: 4796 | N23: 267 | O23: 9 | P23: 244 | Q23: Node={Node$0 | R23: Node$1 | S23: Node$2}left={Node$0->Node$1 | T23: Node$2->Node$0}right={Node$2->Node$0}
A24: binary-tree | B24: binary-tree-l19-c31.result.json | C24: 10 | D24: 10 | E24: 1 | F24: 1 | G24: 3 | H24: 2 | I24: 2 | J24: 5 | K24: 129 | L24: 1352 | M24: 2340 | N24: 124 | O24: 5 | P24: 116 | Q24: Node={Node$0 | R24: Node$1 | S24: Node$2}left={Node$0->Node$2 | T24: Node$1->Node$0 | U24: Node$2->Node$1}right={Node$0->Node$1 | V24: Node$1->Node$0 | W24: Node$2->Node$0}
A25: binary-tree | B25: binary-tree-l7-c24.result.json | C25: 10 | D25: 10 | E25: 1 | F25: 1 | G25: 3 | H25: 2 | I25: 2 | J25: 4 | K25: 129 | L25: 1352 | M25: 2340 | N25: 115 | O25: 5 | P25: 107 | Q25: Node={Node$0 | R25: Node$1 | S25: Node$2}left={Node$0->Node$1 | T25: Node$1->Node$0 | U25: Node$2->Node$0}right={Node$0->Node$2 | V25: Node$1->Node$0 | W25: Node$2->Node$2}
A26: binary-tree | B26: binary-tree-l7-c39.result.json | C26: 10 | D26: 10 | E26: 1 | F26: 1 | G26: 3 | H26: 2 | I26: 2 | J26: 5 | K26: 129 | L26: 1352 | M26: 2340 | N26: 123 | O26: 6 | P26: 114 | Q26: Node={Node$0 | R26: Node$1 | S26: Node$2}left={Node$0->Node$1 | T26: Node$1->Node$2 | U26: Node$2->Node$0}right={Node$0->Node$1 | V26: Node$1->Node$0 | W26: Node$2->Node$0}
A27: class-diagram | B27: class-diagram-l14-c25.result.json | C27: 7 | D27: 9 | E27: 2 | F27: 2 | G27: 4 | H27: 1 | I27: 1 | J27: 2 | K27: 59 | L27: 655 | M27: 1299 | N27: 136 | O27: 8 | P27: 127 | Q27: Class={Object$0 | R27: Class$0 | S27: Class$1}ext={Object$0->Class$1 | T27: Class$1->Class$0}Object={Object$0}
A28: class-diagram | B28: class-diagram-l19-c17.result.json | C28: 2 | D28: 2 | E28: 2 | F28: 2 | G28: 3 | H28: 1 | I28: 1 | J28: 1 | K28: 14 | L28: 90 | M28: 125 | N28: 10 | O28: 2 | P28: 6 | Q28: Class={Object$0 | R28: Class$0}ext={Object$0->Class$0 | S28: Class$0->Class$0}Object={Object$0}
A29: class-diagram | B29: class-diagram-l19-c31.result.json | C29: 7 | D29: 10 | E29: 2 | F29: 2 | G29: 4 | H29: 1 | I29: 1 | J29: 2 | K29: 146 | L29: 1428 | M29: 2809 | N29: 297 | O29: 10 | P29: 284 | Q29: Class={Object$0 | R29: Class$0 | S29: Class$1}ext={Class$0->Object$0 | T29: Class$1->Class$0}Object={Object$0}
A30: class-diagram | B30: class-diagram-l19-c38.result.json | C30: 8 | D30: 9 | E30: 2 | F30: 2 | G30: 4 | H30: 1 | I30: 1 | J30: 2 | K30: 59 | L30: 593 | M30: 1133 | N30: 133 | O30: 8 | P30: 124 | Q30: Class={Object$0 | R30: Class$0 | S30: Class$1}ext={Object$0->Class$0 | T30: Class$0->Class$1 | U30: Class$1->Class$1}Object={Object$0}
A31: class-diagram | B31: class-diagram-l5-c23.result.json | C31: 1 | D31: 1 | E31: 2 | F31: 2 | G31: 3 | H31: 1 | I31: 1 | J31: 1 | K31: 11 | L31: 72 | M31: 98 | N31: 6 | O31: 5 | P31: 0 | Q31: Class={Object$0 | R31: Class$0}ext={Object$0->Class$0 | S31: Class$0->Class$0}Object={Object$0}
A32: class-diagram | B32: class-diagram-l9-c12.result.json | C32: 8 | D32: 8 | E32: 2 | F32: 2 | G32: 4 | H32: 1 | I32: 1 | J32: 2 | K32: 11 | L32: 240 | M32: 516 | N32: 105 | O32: 6 | P32: 97 | Q32: Class={Object$0 | R32: Class$0 | S32: Class$1}ext={Object$0->Class$1 | T32: Class$0->Object$0}Object={Object$0}
A33: classroom | B33: classroom-l10-c21.result.json | C33: 5 | D33: 5 | E33: 5 | F33: 5 | G33: 10 | H33: 3 | I33: 3 | J33: 7 | K33: 60 | L33: 623 | M33: 1017 | N33: 86 | O33: 4 | P33: 80 | Q33: Person={Person$0 | R33: Person$1}Tutors={Person$0->Person$0 | S33: Person$1->Person$0}Teaches={Person$0->Class$0 | T33: Person$0->Class$1 | U33: Person$0->Class$2}Group={Group$0 | V33: Group$1 | W33: Group$2}Class={Class$0 | X33: Class$1 | Y33: Class$2}Groups={Class$0->Person$0->Group$0 | Z33: Class$0->Person$0->Group$1 | AA33: Class$0->Person$0->Group$2 | AB33: Class$1->Person$0->Group$0 | AC33: Class$1->Person$0->Group$1 | AD33: Class$1->Person$0->Group$2 | AE33: Class$2->Person$0->Group$0 | AF33: Class$2->Person$0->Group$1 | AG33: Class$2->Person$0->Group$2}Teacher={Person$0}Student={Person$1}
A34: classroom | B34: classroom-l13-c15.result.json | C34: 4 | D34: 4 | E34: 5 | F34: 5 | G34: 10 | H34: 3 | I34: 3 | J34: 8 | K34: 60 | L34: 606 | M34: 980 | N34: 33 | O34: 4 | P34: 27 | Q34: Person={Person$0 | R34: Person$1}Tutors={Person$0->Person$0 | S34: Person$0->Person$1}Teaches={Person$0->Class$0 | T34: Person$0->Class$1 | U34: Person$0->Class$2}Group={Group$0 | V34: Group$1 | W34: Group$2}Class={Class$0 | X34: Class$1 | Y34: Class$2}Groups={Class$0->Person$0->Group$0 | Z34: Class$0->Person$0->Group$1 | AA34: Class$0->Person$0->Group$2 | AB34: Class$1->Person$0->Group$0 | AC34: Class$1->Person$0->Group$1 | AD34: Class$1->Person$0->Group$2 | AE34: Class$2->Person$0->Group$0 | AF34: Class$2->Person$0->Group$1 | AG34: Class$2->Person$0->Group$2}Teacher={Person$0}Student={Person$1}
A35: classroom | B35: classroom-l15-c15.result.json | C35: 4 | D35: 4 | E35: 5 | F35: 5 | G35: 10 | H35: 3 | I35: 3 | J35: 7 | K35: 60 | L35: 606 | M35: 980 | N35: 41 | O35: 11 | P35: 28 | Q35: Person={Person$0 | R35: Person$1}Tutors={Person$0->Person$0 | S35: Person$1->Person$0}Teaches={Person$0->Class$0 | T35: Person$0->Class$1 | U35: Person$0->Class$2}Group={Group$0 | V35: Group$1 | W35: Group$2}Class={Class$0 | X35: Class$1 | Y35: Class$2}Groups={Class$0->Person$0->Group$0 | Z35: Class$0->Person$0->Group$1 | AA35: Class$0->Person$0->Group$2 | AB35: Class$1->Person$0->Group$0 | AC35: Class$1->Person$0->Group$1 | AD35: Class$1->Person$0->Group$2 | AE35: Class$2->Person$0->Group$0 | AF35: Class$2->Person$0->Group$1 | AG35: Class$2->Person$0->Group$2}Teacher={Person$0}Student={Person$1}
A36: classroom | B36: classroom-l25-c15.result.json | C36: 9 | D36: 9 | E36: 5 | F36: 5 | G36: 10 | H36: 3 | I36: 3 | J36: 7 | K36: 60 | L36: 845 | M36: 1481 | N36: 423 | O36: 10 | P36: 408 | Q36: Person={Person$0 | R36: Person$1 | S36: Person$2}Tutors={Person$0->Person$1 | T36: Person$1->Person$0}Teaches={Person$0->Class$2 | U36: Person$2->Class$1}Group={Group$0}Class={Class$0 | V36: Class$1 | W36: Class$2}Groups={Class$0->Person$0->Group$0 | X36: Class$0->Person$1->Group$0 | Y36: Class$0->Person$2->Group$0 | Z36: Class$1->Person$0->Group$0 | AA36: Class$1->Person$1->Group$0 | AB36: Class$1->Person$2->Group$0 | AC36: Class$2->Person$0->Group$0 | AD36: Class$2->Person$1->Group$0}Teacher={Person$2}Student={Person$1 | AE36: Person$2}
A37: classroom | B37: classroom-l29-c12.result.json | C37: 9 | D37: 9 | E37: 5 | F37: 5 | G37: 9 | H37: 3 | I37: 3 | J37: 7 | K37: 60 | L37: 845 | M37: 1481 | N37: 219 | O37: 4 | P37: 209 | Q37: Person={Person$0 | R37: Person$1 | S37: Person$2}Tutors={Person$0->Person$2 | T37: Person$2->Person$0}Teaches={Person$1->Class$2 | U37: Person$2->Class$1}Group={Group$0}Class={Class$0 | V37: Class$1 | W37: Class$2}Groups={Class$0->Person$0->Group$0 | X37: Class$0->Person$1->Group$0 | Y37: Class$0->Person$2->Group$0 | Z37: Class$1->Person$0->Group$0 | AA37: Class$1->Person$1->Group$0 | AB37: Class$1->Person$2->Group$0}Teacher={Person$1}Student={Person$2}
A38: classroom | B38: classroom-l29-c22.result.json | C38: 9 | D38: 9 | E38: 5 | F38: 5 | G38: 8 | H38: 3 | I38: 2 | J38: 3 | K38: 60 | L38: 845 | M38: 1481 | N38: 201 | O38: 5 | P38: 191 | Q38: Person={Person$0 | R38: Person$1 | S38: Person$2}Tutors={Person$0->Person$2 | T38: Person$1->Person$0}Teaches={Person$1->Class$0}Group={Group$0}Class={Class$0}Teacher={Person$2}Student={Person$1 | U38: Person$2}
A39: classroom | B39: classroom-l33-c15.result.json | C39: 9 | D39: 9 | E39: 5 | F39: 5 | G39: 9 | H39: 3 | I39: 3 | J39: 10 | K39: 60 | L39: 811 | M39: 1517 | N39: 139 | O39: 10 | P39: 128 | Q39: Person={Person$0 | R39: Person$1 | S39: Person$2}Tutors={Person$0->Person$1 | T39: Person$1->Person$2 | U39: Person$2->Person$0}Teaches={Person$1->Class$0 | V39: Person$1->Class$1}Group={Group$0 | W39: Group$1}Class={Class$0 | X39: Class$1}Groups={Class$0->Person$0->Group$1 | Y39: Class$0->Person$1->Group$0 | Z39: Class$0->Person$1->Group$1 | AA39: Class$0->Person$2->Group$0 | AB39: Class$1->Person$0->Group$0}Teacher={Person$1}Student={Person$2}
A40: classroom | B40: classroom-l37-c25.result.json | C40: 9 | D40: 10 | E40: 5 | F40: 4 | G40: 8 | H40: 3 | I40: 3 | J40: 4 | K40: 126 | L40: 1195 | M40: 2121 | N40: 191 | O40: 10 | P40: 180 | Q40: Person={Person$0 | R40: Person$1 | S40: Person$2}Tutors={Person$0->Person$1 | T40: Person$1->Person$2}Teaches={Person$2->Class$0}Group={Group$0}Class={Class$0}Groups={Class$0->Person$1->Group$0}Teacher={Person$0 | U40: Person$1 | V40: Person$2}
...

Sheet 10 target
A1: array | B1: array-l12-c18.result.json | C1: 3 | D1: 4 | E1: 2 | F1: 1 | G1: 1 | H1: 2 | I1: 1 | J1: 1 | K1: 67 | L1: 620 | M1: 1328 | N1: 227 | O1: 15 | P1: 199 | Q1: Array={Array$0}length={Array$0->0}
A2: array | B2: array-l18-c8.result.json | C2: 3 | D2: 4 | E2: 2 | F2: 1 | G2: 1 | H2: 2 | I2: 1 | J2: 1 | K2: 67 | L2: 620 | M2: 1328 | N2: 65 | O2: 9 | P2: 50 | Q2: Array={Array$0}length={Array$0->0}
A3: array | B3: array-l24-c17.result.json | C3: 4 | D3: 4 | E3: 2 | F3: 2 | G3: 2 | H3: 2 | I3: 2 | J3: 2 | K3: 83 | L3: 686 | M3: 1438 | N3: 63 | O3: 10 | P3: 46 | Q3: Element={Element$0}Array={Array$0}i2e={Array$0->0->Element$0}length={Array$0->1}
A4: array | B4: array-l24-c21.result.json | C4: 4 | D4: 4 | E4: 2 | F4: 2 | G4: 2 | H4: 2 | I4: 2 | J4: 2 | K4: 115 | L4: 789 | M4: 1599 | N4: 66 | O4: 15 | P4: 46 | Q4: Element={Element$0}Array={Array$0}i2e={Array$0->0->Element$0}length={Array$0->1}
A5: array | B5: array-l24-c55.result.json | C5: 5 | D5: 5 | E5: 2 | F5: 2 | G5: 2 | H5: 2 | I5: 2 | J5: 2 | K5: 99 | L5: 773 | M5: 1636 | N5: 75 | O5: 13 | P5: 57 | Q5: Element={Element$0}Array={Array$0}i2e={Array$0->0->Element$0}length={Array$0->1}
A6: array | B6: array-l31-c17.result.json | C6: 4 | D6: 4 | E6: 2 | F6: 2 | G6: 2 | H6: 2 | I6: 2 | J6: 2 | K6: 83 | L6: 686 | M6: 1438 | N6: 37 | O6: 8 | P6: 26 | Q6: Element={Element$0}Array={Array$0}i2e={Array$0->0->Element$0}length={Array$0->1}
A7: array | B7: array-l31-c21.result.json | C7: 4 | D7: 4 | E7: 2 | F7: 2 | G7: 2 | H7: 2 | I7: 2 | J7: 2 | K7: 115 | L7: 789 | M7: 1599 | N7: 32 | O7: 7 | P7: 21 | Q7: Element={Element$0}Array={Array$0}i2e={Array$0->0->Element$0}length={Array$0->1}
A8: array | B8: array-l31-c42.result.json | C8: 5 | D8: 5 | E8: 2 | F8: 2 | G8: 2 | H8: 2 | I8: 2 | J8: 2 | K8: 99 | L8: 773 | M8: 1636 | N8: 55 | O8: 10 | P8: 42 | Q8: Element={Element$0}Array={Array$0}i2e={Array$0->0->Element$0}length={Array$0->1}
A9: array | B9: array-l7-c14.result.json | C9: 2 | D9: 2 | E9: 2 | F9: 1 | G9: 1 | H9: 2 | I9: 1 | J9: 1 | K9: 67 | L9: 586 | M9: 1148 | N9: 27 | O9: 8 | P9: 15 | Q9: Array={Array$0}length={Array$0->0}
A10: bempl | B10: bempl-l16-c13.result.json | C10: 5 | D10: 7 | E10: 6 | F10: 5 | G10: 7 | H10: 3 | I10: 2 | J10: 3 | K10: 92 | L10: 847 | M10: 1450 | N10: 167 | O10: 11 | P10: 152 | Q10: Room={secure_lab$0 | R10: Room$0}secure_lab={secure_lab$0}Person={Employee$0}Employee={Employee$0}Key={Key$0 | S10: Key$1}authorized={Key$0->Employee$0 | T10: Key$1->Employee$0}opened_by={Key$0->Room$0 | U10: Key$1->secure_lab$0}
A11: bempl | B11: bempl-l16-c6.result.json | C11: 8 | D11: 10 | E11: 6 | F11: 6 | G11: 8 | H11: 3 | I11: 2 | J11: 2 | K11: 308 | L11: 2093 | M11: 3274 | N11: 368 | O11: 15 | P11: 346 | Q11: Room={secure_lab$0 | R11: Room$0}secure_lab={secure_lab$0}Person={Researcher$0 | S11: Employee$0}Employee={Employee$0}Researcher={Researcher$0}Key={Key$0}authorized={Key$0->Employee$0}opened_by={Key$0->Room$0}
A12: bempl | B12: bempl-l16-c8.result.json | C12: 4 | D12: 4 | E12: 6 | F12: 6 | G12: 7 | H12: 3 | I12: 3 | J12: 3 | K12: 56 | L12: 563 | M12: 923 | N12: 39 | O12: 5 | P12: 31 | Q12: Room={secure_lab$0}secure_lab={secure_lab$0}Person={Employee$0 | R12: Researcher$0}owns={Researcher$0->Key$0}Employee={Employee$0}Researcher={Researcher$0}Key={Key$0}authorized={Key$0->Employee$0}opened_by={Key$0->secure_lab$0}
A13: bempl | B13: bempl-l2-c27.result.json | C13: 5 | D13: 5 | E13: 6 | F13: 5 | G13: 6 | H13: 3 | I13: 0 | J13: 0 | K13: 38 | L13: 392 | M13: 659 | N13: 70 | O13: 6 | P13: 61 | Q13: Room={secure_lab$0}secure_lab={secure_lab$0}Person={Researcher$0 | R13: Employee$0}Employee={Employee$0}Researcher={Researcher$0}
A14: bempl | B14: bempl-l20-c14.result.json | C14: 8 | D14: 8 | E14: 6 | F14: 6 | G14: 7 | H14: 3 | I14: 3 | J14: 3 | K14: 134 | L14: 1171 | M14: 2033 | N14: 120 | O14: 6 | P14: 112 | Q14: Room={secure_lab$0}secure_lab={secure_lab$0}Person={Researcher$0 | R14: Employee$0}owns={Researcher$0->Key$0}Employee={Employee$0}Researcher={Researcher$0}Key={Key$0}authorized={Key$0->Employee$0}opened_by={Key$0->secure_lab$0}
A15: bempl | B15: bempl-l25-c56.result.json | C15: 8 | D15: 10 | E15: 6 | F15: 6 | G15: 12 | H15: 3 | I15: 3 | J15: 3 | K15: 423 | L15: 3088 | M15: 5229 | N15: 260 | O15: 18 | P15: 236 | Q15: Room={secure_lab$0 | R15: Room$0}secure_lab={secure_lab$0}Person={Researcher$0 | S15: Employee$0 | T15: Employee$1 | U15: Researcher$1}owns={Researcher$0->Key$0}Employee={Employee$0 | V15: Employee$1}Researcher={Researcher$0 | W15: Researcher$1}Key={Key$0}authorized={Key$0->Employee$0}opened_by={Key$0->Room$0}
A16: bempl | B16: bempl-l7-c21.result.json | C16: 6 | D16: 6 | E16: 6 | F16: 5 | G16: 7 | H16: 3 | I16: 0 | J16: 0 | K16: 38 | L16: 393 | M16: 661 | N16: 83 | O16: 8 | P16: 73 | Q16: Room={secure_lab$0 | R16: Room$0}secure_lab={secure_lab$0}Person={Researcher$0 | S16: Employee$0}Employee={Employee$0}Researcher={Researcher$0}
A17: bempl | B17: bempl-l8-c23.result.json | C17: 5 | D17: 5 | E17: 6 | F17: 5 | G17: 7 | H17: 3 | I17: 0 | J17: 0 | K17: 38 | L17: 378 | M17: 634 | N17: 39 | O17: 3 | P17: 34 | Q17: Room={secure_lab$0 | R17: Room$0}secure_lab={secure_lab$0}Person={Researcher$0 | S17: Employee$0}Employee={Employee$0}Researcher={Researcher$0}
A18: binary-tree | B18: binary-tree-l11-c25.result.json | C18: 10 | D18: 10 | E18: 1 | F18: 1 | G18: 3 | H18: 2 | I18: 2 | J18: 4 | K18: 129 | L18: 1352 | M18: 2361 | N18: 219 | O18: 11 | P18: 204 | Q18: Node={Node$0 | R18: Node$1 | S18: Node$2}left={Node$0->Node$1 | T18: Node$2->Node$0}right={Node$0->Node$2 | U18: Node$2->Node$1}
A19: binary-tree | B19: binary-tree-l11-c34.result.json | C19: 9 | D19: 10 | E19: 1 | F19: 1 | G19: 3 | H19: 2 | I19: 2 | J19: 4 | K19: 108 | L19: 1097 | M19: 1913 | N19: 126 | O19: 11 | P19: 107 | Q19: Node={Node$0 | R19: Node$1 | S19: Node$2}left={Node$0->Node$1 | T19: Node$1->Node$2}right={Node$0->Node$1 | U19: Node$2->Node$0}
A20: binary-tree | B20: binary-tree-l15-c24.result.json | C20: 10 | D20: 10 | E20: 1 | F20: 1 | G20: 3 | H20: 2 | I20: 2 | J20: 4 | K20: 129 | L20: 1352 | M20: 2361 | N20: 141 | O20: 8 | P20: 129 | Q20: Node={Node$0 | R20: Node$1 | S20: Node$2}left={Node$0->Node$1 | T20: Node$1->Node$2}right={Node$0->Node$2 | U20: Node$2->Node$1}
A21: binary-tree | B21: binary-tree-l15-c33.result.json | C21: 10 | D21: 10 | E21: 1 | F21: 1 | G21: 3 | H21: 2 | I21: 2 | J21: 4 | K21: 129 | L21: 1260 | M21: 2193 | N21: 153 | O21: 11 | P21: 134 | Q21: Node={Node$0 | R21: Node$1 | S21: Node$2}left={Node$0->Node$2 | T21: Node$2->Node$1}right={Node$0->Node$1 | U21: Node$2->Node$0}
A22: binary-tree | B22: binary-tree-l19-c22.result.json | C22: 10 | D22: 10 | E22: 1 | F22: 1 | G22: 3 | H22: 2 | I22: 2 | J22: 4 | K22: 129 | L22: 1352 | M22: 2361 | N22: 122 | O22: 7 | P22: 111 | Q22: Node={Node$0 | R22: Node$1 | S22: Node$2}left={Node$1->Node$0 | T22: Node$2->Node$1}right={Node$0->Node$1 | U22: Node$2->Node$0}
