Workbook

Sheet overall
A1: Total Locations
A2: llms
A3: Syntatically
A4: Length | D4: Alpha | G4: Old Structure | J4: Template Ranked
A5: Top 1 | B5: Top 5 | C5: Top 10 | D5: Top 1 | E5: Top 5 | F5: Top 10 | G5: Top 1 | H5: Top 5 | I5: Top 10 | J5: Top 1 | K5: Top 5 | L5: Top 10
A6: ='llm - syn -len-alpha'!T2 -> 4 | B6: ='llm - syn -len-alpha'!U2 -> 43 | C6: ='llm - syn -len-alpha'!V2 -> 65 | D6: ='llm - syn -len-alpha'!Q2 -> 14 | E6: ='llm - syn -len-alpha'!R2 -> 46 | F6: ='llm - syn -len-alpha'!S2 -> 67 | G6: ='llm - syn -len-alpha'!N2 -> 44 | H6: ='llm - syn -len-alpha'!O2 -> 64 | I6: ='llm - syn -len-alpha'!P2 -> 69 | J6: ='llm - syn -len-alpha'!K2 -> 36 | K6: ='llm - syn -len-alpha'!L2 -> 66 | L6: ='llm - syn -len-alpha'!M2 -> 70
A8: First Correct Encounter
A9: Length | D9: Alpha | G9: Old Structure | J9: Template Ranked
A10: Top 1 | B10: Top 5 | C10: Top 10 | D10: Top 1 | E10: Top 5 | F10: Top 10 | G10: Top 1 | H10: Top 5 | I10: Top 10 | J10: Top 1 | K10: Top 5 | L10: Top 10
A11: ='llm first - length - alpha'!T2 -> 5 | B11: ='llm first - length - alpha'!U2 -> 50 | C11: ='llm first - length - alpha'!V2 -> 75 | D11: ='llm first - length - alpha'!Q2 -> 22 | E11: ='llm first - length - alpha'!R2 -> 58 | F11: ='llm first - length - alpha'!S2 -> 76 | G11: ='llm first - length - alpha'!N2 -> 40 | H11: ='llm first - length - alpha'!O2 -> 73 | I11: ='llm first - length - alpha'!P2 -> 78 | J11: ='llm first - length - alpha'!K2 -> 64 | K11: ='llm first - length - alpha'!L2 -> 79 | L11: ='llm first - length - alpha'!M2 -> 79
A13: Completions
A14: Syntatically
A15: Length | D15: Alpha | G15: Old Structure | J15: Template Ranked
A16: Top 1 | B16: Top 5 | C16: Top 10 | D16: Top 1 | E16: Top 5 | F16: Top 10 | G16: Top 1 | H16: Top 5 | I16: Top 10 | J16: Top 1 | K16: Top 5 | L16: Top 10
A17: ='formula - syn - len alpha'!T2 -> 20 | B17: ='formula - syn - len alpha'!U2 -> 59 | C17: ='formula - syn - len alpha'!V2 -> 88 | D17: ='formula - syn - len alpha'!Q2 -> 17 | E17: ='formula - syn - len alpha'!R2 -> 38 | F17: ='formula - syn - len alpha'!S2 -> 67 | G17: ='formula - syn - len alpha'!N2 -> 25 | H17: ='formula - syn - len alpha'!O2 -> 49 | I17: ='formula - syn - len alpha'!P2 -> 64 | J17: ='formula - syn - len alpha'!K2 -> 39 | K17: ='formula - syn - len alpha'!L2 -> 84 | L17: ='formula - syn - len alpha'!M2 -> 94
A19: First Correct Encounter
A20: Length | D20: Alpha | G20: Old Structure | J20: Template Ranked
A21: Top 1 | B21: Top 5 | C21: Top 10 | D21: Top 1 | E21: Top 5 | F21: Top 10 | G21: Top 1 | H21: Top 5 | I21: Top 10 | J21: Top 1 | K21: Top 5 | L21: Top 10
A22: ='formula - first - len - alpha'!T2 -> 20 | B22: ='formula - first - len - alpha'!U2 -> 61 | C22: ='formula - first - len - alpha'!V2 -> 83 | D22: ='formula - first - len - alpha'!Q2 -> 27 | E22: ='formula - first - len - alpha'!R2 -> 48 | F22: ='formula - first - len - alpha'!S2 -> 73 | G22: ='formula - first - len - alpha'!N2 -> 27 | H22: ='formula - first - len - alpha'!O2 -> 50 | I22: ='formula - first - len - alpha'!P2 -> 67 | J22: ='formula - first - len - alpha'!K2 -> 70 | K22: ='formula - first - len - alpha'!L2 -> 94 | L22: ='formula - first - len - alpha'!M2 -> 99
I24: =9+38+67 -> 114
A25: Correctness | B25: Strat | C25: # Locations | I25: % Locations
C26: Completion Suggestions | F26: LLM | I26: Completion Suggestions | L26: LLM
C27: Top 1 | D27: Top 5 | E27: Top 10 | F27: Top 1 | G27: Top 5 | H27: Top 10 | I27: Top 1 | J27: Top 5 | K27: Top 10 | L27: Top 1 | M27: Top 5 | N27: Top 10
A28: Syntatic | B28: Alpha | C28: =D17 -> 17 | D28: =E17 -> 38 | E28: =F17 -> 67 | F28: =D6 -> 14 | G28: =E6 -> 46 | H28: =F6 -> 67 | I28: =(C28/$I$24)*100 -> 14.912281 | J28: =(D28/$I$24)*100 -> 33.333333 | K28: =(E28/$I$24)*100 -> 58.77193 | L28: =(F28/$I$24)*100 -> 12.280702 | M28: =(G28/$I$24)*100 -> 40.350877 | N28: =(H28/$I$24)*100 -> 58.77193
B29: Length | C29: =A17 -> 20 | D29: =B17 -> 59 | E29: =C17 -> 88 | F29: =A6 -> 4 | G29: =B6 -> 43 | H29: =C6 -> 65 | I29: =(C29/$I$24)*100 -> 17.54386 | J29: =(D29/$I$24)*100 -> 51.754386 | K29: =(E29/$I$24)*100 -> 77.192982 | L29: =(F29/$I$24)*100 -> 3.5087719 | M29: =(G29/$I$24)*100 -> 37.719298 | N29: =(H29/$I$24)*100 -> 57.017544
B30: Templates | C30: =J17 -> 39 | D30: =K17 -> 84 | E30: =L17 -> 94 | F30: =J6 -> 36 | G30: =K6 -> 66 | H30: =L6 -> 70 | I30: =(C30/$I$24)*100 -> 34.210526 | J30: =(D30/$I$24)*100 -> 73.684211 | K30: =(E30/$I$24)*100 -> 82.45614 | L30: =(F30/$I$24)*100 -> 31.578947 | M30: =(G30/$I$24)*100 -> 57.894737 | N30: =(H30/$I$24)*100 -> 61.403509
A31: Semantic | B31: Alpha | C31: =D22 -> 27 | D31: =E22 -> 48 | E31: =F22 -> 73 | F31: =D11 -> 22 | G31: =E11 -> 58 | H31: =F11 -> 76 | I31: =(C31/$I$24)*100 -> 23.684211 | J31: =(D31/$I$24)*100 -> 42.105263 | K31: =(E31/$I$24)*100 -> 64.035088 | L31: =(F31/$I$24)*100 -> 19.298246 | M31: =(G31/$I$24)*100 -> 50.877193 | N31: =(H31/$I$24)*100 -> 66.666667
B32: Length | C32: =A22 -> 20 | D32: =B22 -> 61 | E32: =C22 -> 83 | F32: =A11 -> 5 | G32: =B11 -> 50 | H32: =C11 -> 75 | I32: =(C32/$I$24)*100 -> 17.54386 | J32: =(D32/$I$24)*100 -> 53.508772 | K32: =(E32/$I$24)*100 -> 72.807018 | L32: =(F32/$I$24)*100 -> 4.3859649 | M32: =(G32/$I$24)*100 -> 43.859649 | N32: =(H32/$I$24)*100 -> 65.789474
B33: Templates | C33: =J22 -> 70 | D33: =K22 -> 94 | E33: =L22 -> 99 | F33: =J11 -> 64 | G33: =K11 -> 79 | H33: =L11 -> 79 | I33: =(C33/$I$24)*100 -> 61.403509 | J33: =(D33/$I$24)*100 -> 82.45614 | K33: =(E33/$I$24)*100 -> 86.842105 | L33: =(F33/$I$24)*100 -> 56.140351 | M33: =(G33/$I$24)*100 -> 69.298246 | N33: =(H33/$I$24)*100 -> 69.298246
C36: Template Improvement Over Other Rankings
A38: Strat. | B38: Corr. | C38: Generator | F38: Completion Suggestions
C39: Top 1 | D39: Top 5 | E39: Top 10 | F39: Top 1 | G39: Top 5 | H39: Top 10
A40: Alpha | B40: Syntatic | E40: =(E30-E28/E28)*100 -> 9300 | F40: =(F30-F28/F28)*100 -> 3500 | G40: =(G30-G28/G28)*100 -> 6500 | H40: =(H30-H28/H28)*100 -> 6900
B41: Semantic | E41: =(E33-E31)/E31*100 -> 35.616438 | F41: =(F33-F31)/F31*100 -> 190.90909 | G41: =(G33-G31)/G31*100 -> 36.206897 | H41: =(H33-H31)/H31*100 -> 3.9473684
A42: Length | B42: Syntatic | C42: =(C30-C29)/C29*100 -> 95 | D42: =(D30-D29)/D29*100 -> 42.372881 | E42: =(E30-E29)/E29*100 -> 6.8181818 | F42: =(F30-F29)/F29*100 -> 800 | G42: =(G30-G29)/G29*100 -> 53.488372 | H42: =(H30-H29)/H29*100 -> 7.6923077
B43: Semantic | C43: =(C33-C32)/C32*100 -> 250 | D43: =(D33-D32)/D32*100 -> 54.098361 | E43: =(E33-E32)/E32*100 -> 19.277108 | F43: =(F33-F32)/F32*100 -> 1180 | G43: =(G33-G32)/G32*100 -> 58 | H43: =(H33-H32)/H32*100 -> 5.3333333
C46: Completion improvements over generator
A48: Strat. | B48: Corr. | C48: Top 1 | D48: Top 5 | E48: Top 10
A49: Alpha | B49: Syntatic | E49: =(H28-E28)/E28*100 -> 0
B50: Semantic | C50: =(F29-C29)/C29*100 -> -80 | D50: =(G29-D29)/D29*100 -> -27.118644 | E50: =(H29-E29)/E29*100 -> -26.136364
...

Sheet accuracy details
A1: model | B1: # exact | C1: loc exact | D1: start | E1: loc start | F1: loc start or match | G1: # sem | H1: loc sem | I1: total sug | J1: % valid | L1: model | M1: # exact | N1: loc exact | O1: start | P1: loc start | Q1: loc start or match | R1: # sem | S1: loc sem | T1: total sug | U1: % valid
A2: array | B2: 9 | C2: 9 | D2: 2 | E2: 2 | F2: 9 | G2: 25 | H2: 9 | I2: 54 | J2: =G2/I2*100 -> 46.296296 | L2: array | M2: 5 | N2: 5 | O2: 0 | P2: 0 | Q2: 5 | R2: 12 | S2: 5 | T2: 64 | U2: =R2/T2*100 -> 18.75
A3: classroom-fol | B3: 34 | C3: 34 | D3: 4 | E3: 4 | F3: 37 | G3: 2289 | H3: 35 | I3: 2670 | J3: =G3/I3*100 -> 85.730337 | L3: classroom-fol | M3: 30 | N3: 30 | O3: 1 | P3: 1 | Q3: 35 | R3: 342 | S3: 35 | T3: 485 | U3: =R3/T3*100 -> 70.515464
A4: courses-v2 | B4: 58 | C4: 58 | D4: 15 | E4: 15 | F4: 61 | G4: 1668 | H4: 59 | I4: 2794 | J4: =G4/I4*100 -> 59.699356 | L4: courses-v2 | M4: 36 | N4: 36 | O4: 4 | P4: 4 | Q4: 40 | R4: 297 | S4: 40 | T4: 454 | U4: =R4/T4*100 -> 65.418502
B5: =SUM(B2:B4) -> 101 | C5: =SUM(C2:C4) -> 101 | D5: =SUM(D2:D4) -> 21 | E5: =SUM(E2:E4) -> 21 | F5: =SUM(F2:F4) -> 107 | G5: =SUM(G2:G4) -> 3982 | H5: =SUM(H2:H4) -> 103 | I5: =SUM(I2:I4) -> 5518 | J5: =G5/I5*100 -> 72.163827 | M5: =SUM(M2:M4) -> 71 | N5: =SUM(N2:N4) -> 71 | O5: =SUM(O2:O4) -> 5 | P5: =SUM(P2:P4) -> 5 | Q5: =SUM(Q2:Q4) -> 80 | R5: =SUM(R2:R4) -> 651 | S5: =SUM(S2:S4) -> 80 | T5: =SUM(T2:T4) -> 1003 | U5: =R5/T5*100 -> 64.905284
A7: Model | B7: # Loc | C7: Formula Completions | G7: Generator
C8: Locations With | F8: % Valid | H8: Locations With | J8: % Valid
C9: Syn | D9: Sem | E9: Start + | G9: Syn | H9: Sem | I9: Start +
A10: array | B10: 9 | C10: =B2 -> 9 | D10: =H2 -> 9 | E10: =F2 -> 9 | F10: =J2 -> 46.296296 | G10: =M2 -> 5 | H10: =S2 -> 5 | I10: =Q2 -> 5 | J10: =U2 -> 18.75
A11: classroom-rl | B11: 38 | C11: =B3 -> 34 | D11: =H3 -> 35 | E11: =F3 -> 37 | F11: =J3 -> 85.730337 | G11: =M3 -> 30 | H11: =S3 -> 35 | I11: =Q3 -> 35 | J11: =U3 -> 70.515464
A12: courses-v2 | B12: 67 | C12: =B4 -> 58 | D12: =H4 -> 59 | E12: =F4 -> 61 | F12: =J4 -> 59.699356 | G12: =M4 -> 36 | H12: =S4 -> 40 | I12: =Q4 -> 40 | J12: =U4 -> 65.418502
B13: =SUM(B10:B12) -> 114 | C13: =SUM(C10:C12) -> 101 | D13: =SUM(D10:D12) -> 103 | E13: =SUM(E10:E12) -> 107 | F13: =J5 -> 72.163827 | G13: =M5 -> 71 | H13: =S5 -> 80 | I13: =Q5 -> 80 | J13: =U5 -> 64.905284

Sheet performance
A2: array | B2: 9 | C2: 54 | D2: 64 | E2: =(C2-D2)/C2*100 -> -18.518519 | F2: 6 | G2: =D2/B2 -> 7.1111111 | H2: =(F2-G2)/F2*100 -> -18.518519 | I2: 51 | J2: 19122.62 | K2: =I2-J2 -> -19071.62
A3: classroom-fol | B3: 38 | C3: 2670 | D3: 485 | E3: =(C3-D3)/C3*100 -> 81.835206 | F3: 70 | G3: =D3/B3 -> 12.763158 | H3: =(F3-G3)/F3*100 -> 81.766917 | I3: 21 | J3: 26219.96 | K3: =I3-J3 -> -26198.96
A4: courses-v2 | B4: 67 | C4: 2794 | D4: 454 | E4: =(C4-D4)/C4*100 -> 83.750895 | F4: 42 | G4: =D4/B4 -> 6.7761194 | H4: =(F4-G4)/F4*100 -> 83.866382 | I4: 27 | J4: 13183.33 | K4: =I4-J4 -> -13156.33
B5: =SUM(B2:B4) -> 114 | C5: =SUM(C2:C4) -> 5518 | D5: =SUM(D2:D4) -> 1003 | E5: =(C5-D5)/C5*100 -> 81.823124 | F5: =SUM(F2:F4) -> 118 | G5: =SUM(G2:G4) -> 26.650388 | H5: =(F5-G5)/F5*100 -> 77.414925 | I5: =SUM(I2:I4) -> 99 | J5: =SUM(J2:J4) -> 58525.91 | K5: =I5-J5 -> -58426.91 | L5: =K5/1000 -> -58.42691

Sheet llm - syn -len-alpha
A1: i2e | B1: 1 | C1: 2 | D1: 1 | E1: 1 | F1: 1 | G1: TRUE | H1: TRUE | I1: TRUE | K1: top 1 | L1: top 5 | M1: top 10 | N1: top 1 | O1: top 5 | P1: top 10 | Q1: top 1 | R1: top 5 | S1: top 10 | T1: top 1 | U1: top 5 | V1: top 10
A2: length | B2: 2 | C2: 1 | D2: 6 | E2: 7 | F2: 1 | G2: TRUE | H2: TRUE | I2: TRUE | K2: =COUNTIF(B1:B1000,"=1") -> 36 | L2: =COUNTIF(B1:B1000,"<=5") -> 66 | M2: =COUNTIF(B1:B1000,"<=10") -> 70 | N2: =COUNTIF(C1:C1000,"=1") -> 44 | O2: =COUNTIF(C1:C1000,"<=5") -> 64 | P2: =COUNTIF(C1:C1000,"<=10") -> 69 | Q2: =COUNTIF(D1:D1000,"=1") -> 14 | R2: =COUNTIF(D1:D1000,"<=5") -> 46 | S2: =COUNTIF(D1:D1000,"<=10") -> 67 | T2: =COUNTIF(E1:E1000,"=1") -> 4 | U2: =COUNTIF(E1:E1000,"<=5") -> 43 | V2: =COUNTIF(E1:E1000,"<=10") -> 65
A3: Element | B3: 1 | C3: 2 | D3: 3 | E3: 3 | F3: 3 | G3: TRUE | H3: TRUE | I3: TRUE
A4: length | B4: 2 | C4: 1 | D4: 6 | E4: 4 | F4: 1 | G4: TRUE | H4: TRUE | I4: TRUE
A5: Element | B5: 1 | C5: 1 | D5: 1 | E5: 3 | F5: 1 | G5: TRUE | H5: TRUE | I5: TRUE
A6: Person | B6: 1 | C6: 1 | D6: 1 | E6: 2 | F6: 1 | G6: TRUE | H6: TRUE | I6: TRUE
A7: Person | B7: 1 | C7: 1 | D7: 1 | E7: 5 | F7: 2 | G7: TRUE | H7: TRUE | I7: TRUE
A8: Student | B8: 3 | C8: 3 | D8: 3 | E8: 6 | F8: 2 | G8: TRUE | H8: TRUE | I8: TRUE
A9: Teacher | B9: 5 | C9: 7 | D9: 6 | E9: 6 | F9: 6 | G9: TRUE | H9: TRUE | I9: TRUE
A10: Student | B10: 3 | C10: 3 | D10: 2 | E10: 7 | F10: 2 | G10: TRUE | H10: TRUE | I10: TRUE
A11: Teacher | B11: 6 | C11: 2 | D11: 3 | E11: 9 | F11: 6 | G11: TRUE | H11: TRUE | I11: TRUE
A12: Student | B12: 3 | C12: 3 | D12: 2 | E12: 9 | F12: 2 | G12: TRUE | H12: TRUE | I12: TRUE
A13: Teacher | B13: 3 | C13: 1 | D13: 2 | E13: 4 | F13: 2 | G13: TRUE | H13: TRUE | I13: TRUE
A14: Teaches | B14: 1 | C14: 2 | D14: 2 | E14: 4 | F14: 1 | G14: TRUE | H14: TRUE | I14: TRUE
... A71: Person | B71: 1 | C71: 1 | D71: 4 | E71: 4 | F71: 2 | G71: TRUE | H71: TRUE | I71: TRUE

Sheet llm first - length - alpha
A1: i2e | B1: 1 | C1: 2 | D1: 1 | E1: 1 | F1: 1 | G1: TRUE | H1: TRUE | I1: TRUE | K1: top 1 | L1: top 5 | M1: top 10 | N1: top 1 | O1: top 5 | P1: top 10 | Q1: top 1 | R1: top 5 | S1: top 10 | T1: top 1 | U1: top 5 | V1: top 10
A2: length | B2: 2 | C2: 1 | D2: 6 | E2: 7 | F2: 1 | G2: TRUE | H2: TRUE | I2: TRUE | K2: =COUNTIF(B1:B1000,"=1") -> 64 | L2: =COUNTIF(B1:B1000,"<=5") -> 79 | M2: =COUNTIF(B1:B1000,"<=10") -> 79 | N2: =COUNTIF(C1:C1000,"=1") -> 40 | O2: =COUNTIF(C1:C1000,"<=5") -> 73 | P2: =COUNTIF(C1:C1000,"<=10") -> 78 | Q2: =COUNTIF(D1:D1000,"=1") -> 22 | R2: =COUNTIF(D1:D1000,"<=5") -> 58 | S2: =COUNTIF(D1:D1000,"<=10") -> 76 | T2: =COUNTIF(E1:E1000,"=1") -> 5 | U2: =COUNTIF(E1:E1000,"<=5") -> 50 | V2: =COUNTIF(E1:E1000,"<=10") -> 75
A3: Element | B3: 1 | C3: 2 | D3: 3 | E3: 3 | F3: 3 | G3: TRUE | H3: TRUE | I3: TRUE
A4: length | B4: 2 | C4: 1 | D4: 6 | E4: 4 | F4: 1 | G4: TRUE | H4: TRUE | I4: TRUE
A5: Element | B5: 1 | C5: 1 | D5: 1 | E5: 3 | F5: 1 | G5: TRUE | H5: TRUE | I5: TRUE
A6: Person | B6: 1 | C6: 1 | D6: 1 | E6: 2 | F6: 1 | G6: TRUE | H6: TRUE | I6: TRUE
A7: Person | B7: 1 | C7: 1 | D7: 1 | E7: 5 | F7: 2 | G7: TRUE | H7: TRUE | I7: TRUE
A8: p.Tutors | B8: 1 | C8: 6 | D8: 10 | E8: 9 | F8: 1 | G8: FALSE | H8: FALSE | I8: TRUE
A9: p.Tutors | B9: 1 | C9: 2 | D9: 10 | E9: 8 | F9: 1 | G9: FALSE | H9: FALSE | I9: TRUE
A10: p.Tutors | B10: 1 | C10: 5 | D10: 5 | E10: 9 | F10: 1 | G10: FALSE | H10: FALSE | I10: TRUE
A11: p.Tutors | B11: 1 | C11: 4 | D11: 5 | E11: 10 | F11: 1 | G11: FALSE | H11: FALSE | I11: TRUE
A12: p.Tutors | B12: 1 | C12: 6 | D12: 6 | E12: 11 | F12: 1 | G12: FALSE | H12: FALSE | I12: TRUE
A13: p.Tutors | B13: 1 | C13: 4 | D13: 6 | E13: 6 | F13: 1 | G13: FALSE | H13: FALSE | I13: TRUE
A14: Teaches | B14: 1 | C14: 2 | D14: 2 | E14: 4 | F14: 1 | G14: TRUE | H14: TRUE | I14: TRUE
... A80: Person | B80: 1 | C80: 1 | D80: 4 | E80: 4 | F80: 2 | G80: TRUE | H80: TRUE | I80: TRUE

Sheet formula - syn - len alpha
A1: i2e | B1: 1 | C1: 2 | D1: 1 | E1: 1 | F1: 1 | G1: TRUE | H1: TRUE | I1: TRUE | K1: top 1 | L1: top 5 | M1: top 10 | N1: top 1 | O1: top 5 | P1: top 10 | Q1: top 1 | R1: top 5 | S1: top 10 | T1: top 1 | U1: top 5 | V1: top 10
A2: length | B2: 2 | C2: 4 | D2: 4 | E2: 2 | F2: 1 | G2: TRUE | H2: TRUE | I2: TRUE | K2: =COUNTIF(B1:B1000,"=1") -> 39 | L2: =COUNTIF(B1:B1000,"<=5") -> 84 | M2: =COUNTIF(B1:B1000,"<=10") -> 94 | N2: =COUNTIF(C1:C1000,"=1") -> 25 | O2: =COUNTIF(C1:C1000,"<=5") -> 49 | P2: =COUNTIF(C1:C1000,"<=10") -> 64 | Q2: =COUNTIF(D1:D1000,"=1") -> 17 | R2: =COUNTIF(D1:D1000,"<=5") -> 38 | S2: =COUNTIF(D1:D1000,"<=10") -> 67 | T2: =COUNTIF(E1:E1000,"=1") -> 20 | U2: =COUNTIF(E1:E1000,"<=5") -> 59 | V2: =COUNTIF(E1:E1000,"<=10") -> 88
A3: i2e.Element | B3: 4 | C3: 1 | D3: 2 | E3: 5 | F3: 200021 | G3: TRUE | H3: TRUE | I3: TRUE
A4: Element | B4: 1 | C4: 1 | D4: 1 | E4: 2 | F4: 3 | G4: TRUE | H4: TRUE | I4: TRUE
A5: i2e.Element | B5: 4 | C5: 1 | D5: 2 | E5: 5 | F5: 200021 | G5: TRUE | H5: TRUE | I5: TRUE
A6: Element | B6: 1 | C6: 1 | D6: 1 | E6: 2 | F6: 3 | G6: TRUE | H6: TRUE | I6: TRUE
A7: i2e | B7: 1 | C7: 3 | D7: 1 | E7: 1 | F7: 1 | G7: TRUE | H7: TRUE | I7: TRUE
A8: Person | B8: 3 | C8: 3 | D8: 4 | E8: 6 | F8: 1 | G8: TRUE | H8: TRUE | I8: TRUE
A9: Person | B9: 3 | C9: 3 | D9: 4 | E9: 6 | F9: 2 | G9: TRUE | H9: TRUE | I9: TRUE
A10: Student | B10: 5 | C10: 61 | D10: 45 | E10: 9 | F10: 2 | G10: TRUE | H10: TRUE | I10: TRUE
A11: Teacher | B11: 8 | C11: 66 | D11: 50 | E11: 10 | F11: 6 | G11: TRUE | H11: TRUE | I11: TRUE
A12: Student | B12: 5 | C12: 61 | D12: 45 | E12: 9 | F12: 2 | G12: TRUE | H12: TRUE | I12: TRUE
A13: Teacher | B13: 8 | C13: 66 | D13: 50 | E13: 10 | F13: 6 | G13: TRUE | H13: TRUE | I13: TRUE
A14: Student | B14: 5 | C14: 61 | D14: 45 | E14: 9 | F14: 2 | G14: TRUE | H14: TRUE | I14: TRUE
... A99: grades | B99: 1 | C99: 14 | D99: 1 | E99: 1 | F99: 1 | G99: TRUE | H99: TRUE | I99: TRUE

Sheet formula - first - len - alpha
A1: i2e | B1: 1 | C1: 2 | D1: 1 | E1: 1 | F1: 1 | G1: TRUE | H1: TRUE | I1: TRUE | K1: top 1 | L1: top 5 | M1: top 10 | N1: top 1 | O1: top 5 | P1: top 10 | Q1: top 1 | R1: top 5 | S1: top 10 | T1: top 1 | U1: top 5 | V1: top 10
A2: length | B2: 2 | C2: 4 | D2: 4 | E2: 2 | F2: 1 | G2: TRUE | H2: TRUE | I2: TRUE | K2: =COUNTIF(B1:B1000,"=1") -> 70 | L2: =COUNTIF(B1:B1000,"<=5") -> 94 | M2: =COUNTIF(B1:B1000,"<=10") -> 99 | N2: =COUNTIF(C1:C1000,"=1") -> 27 | O2: =COUNTIF(C1:C1000,"<=5") -> 50 | P2: =COUNTIF(C1:C1000,"<=10") -> 67 | Q2: =COUNTIF(D1:D1000,"=1") -> 27 | R2: =COUNTIF(D1:D1000,"<=5") -> 48 | S2: =COUNTIF(D1:D1000,"<=10") -> 73 | T2: =COUNTIF(E1:E1000,"=1") -> 20 | U2: =COUNTIF(E1:E1000,"<=5") -> 61 | V2: =COUNTIF(E1:E1000,"<=10") -> 83
A3: i2e.Element | B3: 4 | C3: 1 | D3: 2 | E3: 5 | F3: 200021 | G3: TRUE | H3: TRUE | I3: TRUE
A4: Element | B4: 1 | C4: 1 | D4: 1 | E4: 2 | F4: 3 | G4: TRUE | H4: TRUE | I4: TRUE
A5: i2e.Element | B5: 4 | C5: 1 | D5: 2 | E5: 5 | F5: 200021 | G5: TRUE | H5: TRUE | I5: TRUE
A6: Element | B6: 1 | C6: 1 | D6: 1 | E6: 2 | F6: 3 | G6: TRUE | H6: TRUE | I6: TRUE
A7: i2e | B7: 1 | C7: 3 | D7: 1 | E7: 1 | F7: 1 | G7: TRUE | H7: TRUE | I7: TRUE
A8: Person | B8: 3 | C8: 3 | D8: 4 | E8: 6 | F8: 1 | G8: TRUE | H8: TRUE | I8: TRUE
A9: Person | B9: 3 | C9: 3 | D9: 4 | E9: 6 | F9: 2 | G9: TRUE | H9: TRUE | I9: TRUE
A10: p.Tutors | B10: 1 | C10: 18 | D10: 122 | E10: 12 | F10: 1 | G10: FALSE | H10: FALSE | I10: TRUE
A11: p.Tutors | B11: 1 | C11: 18 | D11: 122 | E11: 12 | F11: 1 | G11: FALSE | H11: FALSE | I11: TRUE
A12: p.Tutors | B12: 1 | C12: 18 | D12: 122 | E12: 12 | F12: 1 | G12: FALSE | H12: FALSE | I12: TRUE
A13: p.Tutors | B13: 1 | C13: 18 | D13: 122 | E13: 12 | F13: 1 | G13: FALSE | H13: FALSE | I13: TRUE
A14: p.Tutors | B14: 1 | C14: 18 | D14: 122 | E14: 12 | F14: 1 | G14: FALSE | H14: FALSE | I14: TRUE
... A100: grades | B100: 1 | C100: 14 | D100: 1 | E100: 1 | F100: 1 | G100: TRUE | H100: TRUE | I100: TRUE
