Workbook

Sheet overall
A1: Benchmark | Q1: Large | AG1: Combined
A2: Total Locations | C2: 625 | Q2: Total Locations | S2: =365+261+99+111+89 -> 925 | AG2: Total Locations | AI2: =I25+S2 -> 1550
A3: Completion Suggestions | Q3: Completion Suggestions | AG3: Completion Suggestions
A4: Syntatically | Q4: Syntatically | AG4: Syntatically
A5: Length | D5: Alpha | G5: Template Ranked | Q5: Length | T5: Alpha | W5: Template Ranked | AG5: Length | AJ5: Alpha | AM5: Template Ranked
A6: Top 1 | B6: Top 5 | C6: Top 10 | D6: Top 1 | E6: Top 5 | F6: Top 10 | G6: Top 1 | H6: Top 5 | I6: Top 10 | Q6: Top 1 | R6: Top 5 | S6: Top 10 | T6: Top 1 | U6: Top 5 | V6: Top 10 | W6: Top 1 | X6: Top 5 | Y6: Top 10 | AG6: Top 1 | AH6: Top 5 | AI6: Top 10 | AJ6: Top 1 | AK6: Top 5 | AL6: Top 10 | AM6: Top 1 | AN6: Top 5 | AO6: Top 10
A7: ='formula - syn -len-alpha'!T2 -> 97 | B7: ='formula - syn -len-alpha'!U2 -> 270 | C7: ='formula - syn -len-alpha'!V2 -> 450 | D7: ='formula - syn -len-alpha'!Q2 -> 86 | E7: ='formula - syn -len-alpha'!R2 -> 172 | F7: ='formula - syn -len-alpha'!S2 -> 267 | G7: ='formula - syn -len-alpha'!K2 -> 193 | H7: ='formula - syn -len-alpha'!L2 -> 461 | I7: ='formula - syn -len-alpha'!M2 -> 517 | Q7: ='formula - syn - large'!Q2 -> 139 | R7: ='formula - syn - large'!R2 -> 392 | S7: ='formula - syn - large'!S2 -> 509 | T7: ='formula - syn - large'!N2 -> 75 | U7: ='formula - syn - large'!O2 -> 110 | V7: ='formula - syn - large'!P2 -> 259 | W7: ='formula - syn - large'!K2 -> 204 | X7: ='formula - syn - large'!L2 -> 524 | Y7: ='formula - syn - large'!M2 -> 630 | AG7: =A7+Q7 -> 236 | AH7: =B7+R7 -> 662 | AI7: =C7+S7 -> 959 | AJ7: =D7+T7 -> 161 | AK7: =E7+U7 -> 282 | AL7: =F7+V7 -> 526 | AM7: =G7+W7 -> 397 | AN7: =H7+X7 -> 985 | AO7: =I7+Y7 -> 1147
A9: First Correct Encounter | Q9: First Correct Encounter | AG9: First Correct Encounter
A10: Length | D10: Alpha | G10: Template Ranked | Q10: Length | T10: Alpha | W10: Template Ranked | AG10: Length | AJ10: Alpha | AM10: Template Ranked
A11: Top 1 | B11: Top 5 | C11: Top 10 | D11: Top 1 | E11: Top 5 | F11: Top 10 | G11: Top 1 | H11: Top 5 | I11: Top 10 | Q11: Top 1 | R11: Top 5 | S11: Top 10 | T11: Top 1 | U11: Top 5 | V11: Top 10 | W11: Top 1 | X11: Top 5 | Y11: Top 10 | AG11: Top 1 | AH11: Top 5 | AI11: Top 10 | AJ11: Top 1 | AK11: Top 5 | AL11: Top 10 | AM11: Top 1 | AN11: Top 5 | AO11: Top 10
A12: ='formula first - length - alpha'!T2 -> 131 | B12: ='formula first - length - alpha'!U2 -> 315 | C12: ='formula first - length - alpha'!V2 -> 474 | D12: ='formula first - length - alpha'!Q2 -> 111 | E12: ='formula first - length - alpha'!R2 -> 201 | F12: ='formula first - length - alpha'!S2 -> 282 | G12: ='formula first - length - alpha'!K2 -> 398 | H12: ='formula first - length - alpha'!L2 -> 540 | I12: ='formula first - length - alpha'!M2 -> 562 | Q12: ='formula - first - large'!Q2 -> 143 | R12: ='formula - first - large'!R2 -> 419 | S12: ='formula - first - large'!S2 -> 518 | T12: ='formula - first - large'!N2 -> 142 | U12: ='formula - first - large'!O2 -> 188 | V12: ='formula - first - large'!P2 -> 363 | W12: ='formula - first - large'!K2 -> 464 | X12: ='formula - first - large'!L2 -> 679 | Y12: ='formula - first - large'!M2 -> 738 | AG12: =A12+Q12 -> 274 | AH12: =B12+R12 -> 734 | AI12: =C12+S12 -> 992 | AJ12: =D12+T12 -> 253 | AK12: =E12+U12 -> 389 | AL12: =F12+V12 -> 645 | AM12: =G12+W12 -> 862 | AN12: =H12+X12 -> 1219 | AO12: =I12+Y12 -> 1300
A14: Baseline Generator | Q14: Baseline Generator | AG14: Baseline Generator
A15: Syntatically | Q15: Syntatically | AG15: Syntatically
A16: Length | D16: Alpha | G16: Template Ranked | Q16: Length | T16: Alpha | W16: Template Ranked | AG16: Length | AJ16: Alpha | AM16: Template Ranked
A17: Top 1 | B17: Top 5 | C17: Top 10 | D17: Top 1 | E17: Top 5 | F17: Top 10 | G17: Top 1 | H17: Top 5 | I17: Top 10 | Q17: Top 1 | R17: Top 5 | S17: Top 10 | T17: Top 1 | U17: Top 5 | V17: Top 10 | W17: Top 1 | X17: Top 5 | Y17: Top 10 | AG17: Top 1 | AH17: Top 5 | AI17: Top 10 | AJ17: Top 1 | AK17: Top 5 | AL17: Top 10 | AM17: Top 1 | AN17: Top 5 | AO17: Top 10
A18: ='gen - syn - len alpha'!T2 -> 31 | B18: ='gen - syn - len alpha'!U2 -> 111 | C18: ='gen - syn - len alpha'!V2 -> 244 | D18: ='gen - syn - len alpha'!Q2 -> 0 | E18: ='gen - syn - len alpha'!R2 -> 0 | F18: ='gen - syn - len alpha'!S2 -> 1 | G18: ='gen - syn - len alpha'!K2 -> 105 | H18: ='gen - syn - len alpha'!L2 -> 353 | I18: ='gen - syn - len alpha'!M2 -> 404 | Q18: ='gen - syn - large'!Q2 -> 83 | R18: ='gen - syn - large'!R2 -> 214 | S18: ='gen - syn - large'!S2 -> 267 | T18: ='gen - syn - large'!N2 -> 0 | U18: ='gen - syn - large'!O2 -> 0 | V18: ='gen - syn - large'!P2 -> 0 | W18: ='gen - syn - large'!K2 -> 83 | X18: ='gen - syn - large'!L2 -> 340 | Y18: ='gen - syn - large'!M2 -> 407 | AG18: =A18+Q18 -> 114 | AH18: =B18+R18 -> 325 | AI18: =C18+S18 -> 511 | AJ18: =D18+T18 -> 0 | AK18: =E18+U18 -> 0 | AL18: =F18+V18 -> 1 | AM18: =G18+W18 -> 188 | AN18: =H18+X18 -> 693 | AO18: =I18+Y18 -> 811
A20: First Correct Encounter | Q20: First Correct Encounter | AG20: First Correct Encounter
A21: Length | D21: Alpha | G21: Template Ranked | Q21: Length | T21: Alpha | W21: Template Ranked | AG21: Length | AJ21: Alpha | AM21: Template Ranked
A22: Top 1 | B22: Top 5 | C22: Top 10 | D22: Top 1 | E22: Top 5 | F22: Top 10 | G22: Top 1 | H22: Top 5 | I22: Top 10 | Q22: Top 1 | R22: Top 5 | S22: Top 10 | T22: Top 1 | U22: Top 5 | V22: Top 10 | W22: Top 1 | X22: Top 5 | Y22: Top 10 | AG22: Top 1 | AH22: Top 5 | AI22: Top 10 | AJ22: Top 1 | AK22: Top 5 | AL22: Top 10 | AM22: Top 1 | AN22: Top 5 | AO22: Top 10
A23: ='gen - first - len - alpha'!T2 -> 43 | B23: ='gen - first - len - alpha'!U2 -> 159 | C23: ='gen - first - len - alpha'!V2 -> 319 | D23: ='gen - first - len - alpha'!Q2 -> 2 | E23: ='gen - first - len - alpha'!R2 -> 3 | F23: ='gen - first - len - alpha'!S2 -> 4 | G23: ='gen - first - len - alpha'!K2 -> 340 | H23: ='gen - first - len - alpha'!L2 -> 510 | I23: ='gen - first - len - alpha'!M2 -> 542 | Q23: ='gen - first - large'!Q2 -> 133 | R23: ='gen - first - large'!R2 -> 213 | S23: ='gen - first - large'!S2 -> 327 | T23: ='gen - first - large'!N2 -> 0 | U23: ='gen - first - large'!O2 -> 0 | V23: ='gen - first - large'!P2 -> 0 | W23: ='gen - first - large'!K2 -> 290 | X23: ='gen - first - large'!L2 -> 528 | Y23: ='gen - first - large'!M2 -> 588 | AG23: =A23+Q23 -> 176 | AH23: =B23+R23 -> 372 | AI23: =C23+S23 -> 646 | AJ23: =D23+T23 -> 2 | AK23: =E23+U23 -> 3 | AL23: =F23+V23 -> 4 | AM23: =G23+W23 -> 630 | AN23: =H23+X23 -> 1038 | AO23: =I23+Y23 -> 1130
I25: 625
A26: Correctness | B26: Strat | C26: # Locations | I26: % Locations | Q26: Correctness | R26: Strat | S26: # Locations | Y26: % Locations | AG26: Correctness | AH26: Strat | AI26: # Locations | AO26: % Locations
C27: Generator | F27: Completion Suggestions | I27: Generator | L27: Completion Suggestions | S27: Generator | V27: Completion Suggestions | Y27: Generator | AB27: Completion Suggestions | AI27: Generator | AL27: Completion Suggestions | AO27: Generator | AR27: Completion Suggestions
C28: Top 1 | D28: Top 5 | E28: Top 10 | F28: Top 1 | G28: Top 5 | H28: Top 10 | I28: Top 1 | J28: Top 5 | K28: Top 10 | L28: Top 1 | M28: Top 5 | N28: Top 10 | S28: Top 1 | T28: Top 5 | U28: Top 10 | V28: Top 1 | W28: Top 5 | X28: Top 10 | Y28: Top 1 | Z28: Top 5 | AA28: Top 10 | AB28: Top 1 | AC28: Top 5 | AD28: Top 10 | AI28: Top 1 | AJ28: Top 5 | AK28: Top 10 | AL28: Top 1 | AM28: Top 5 | AN28: Top 10 | AO28: Top 1 | AP28: Top 5 | AQ28: Top 10 | AR28: Top 1 | AS28: Top 5 | AT28: Top 10
A29: Syntatic | B29: Alpha | C29: =D18 -> 0 | D29: =E18 -> 0 | E29: =F18 -> 1 | F29: =D7 -> 86 | G29: =E7 -> 172 | H29: =F7 -> 267 | I29: =(C29/$I$25)*100 -> 0 | J29: =(D29/$I$25)*100 -> 0 | K29: =(E29/$I$25)*100 -> 0.16 | L29: =(F29/$I$25)*100 -> 13.76 | M29: =(G29/$I$25)*100 -> 27.52 | N29: =(H29/$I$25)*100 -> 42.72 | Q29: Syntatic-L | R29: Alpha | S29: =T18 -> 0 | T29: =U18 -> 0 | U29: =V18 -> 0 | V29: =T7 -> 75 | W29: =U7 -> 110 | X29: =V7 -> 259 | Y29: =(S29/$S$2)*100 -> 0 | Z29: =(T29/$S$2)*100 -> 0 | AA29: =(U29/$S$2)*100 -> 0 | AB29: =(V29/$S$2)*100 -> 8.1081081 | AC29: =(W29/$S$2)*100 -> 11.891892 | AD29: =(X29/$S$2)*100 -> 28 | AG29: Syntatic | AH29: Alpha | AI29: =AJ18 -> 0 | AJ29: =AK18 -> 0 | AK29: =AL18 -> 1 | AL29: =AJ7 -> 161 | AM29: =AK7 -> 282 | AN29: =AL7 -> 526 | AO29: =(AI29/$AI$2)*100 -> 0 | AP29: =(AJ29/$AI$2)*100 -> 0 | AQ29: =(AK29/$AI$2)*100 -> 0.064516129 | AR29: =(AL29/$AI$2)*100 -> 10.387097 | AS29: =(AM29/$AI$2)*100 -> 18.193548 | AT29: =(AN29/$AI$2)*100 -> 33.935484
B30: Length | C30: =A18 -> 31 | D30: =B18 -> 111 | E30: =C18 -> 244 | F30: =A7 -> 97 | G30: =B7 -> 270 | H30: =C7 -> 450 | I30: =(C30/$I$25)*100 -> 4.96 | J30: =(D30/$I$25)*100 -> 17.76 | K30: =(E30/$I$25)*100 -> 39.04 | L30: =(F30/$I$25)*100 -> 15.52 | M30: =(G30/$I$25)*100 -> 43.2 | N30: =(H30/$I$25)*100 -> 72 | R30: Length | S30: =Q18 -> 83 | T30: =R18 -> 214 | U30: =S18 -> 267 | V30: =Q7 -> 139 | W30: =R7 -> 392 | X30: =S7 -> 509 | Y30: =(S30/$S$2)*100 -> 8.972973 | Z30: =(T30/$S$2)*100 -> 23.135135 | AA30: =(U30/$S$2)*100 -> 28.864865 | AB30: =(V30/$S$2)*100 -> 15.027027 | AC30: =(W30/$S$2)*100 -> 42.378378 | AD30: =(X30/$S$2)*100 -> 55.027027 | AH30: Length | AI30: =AG18 -> 114 | AJ30: =AH18 -> 325 | AK30: =AI18 -> 511 | AL30: =AG7 -> 236 | AM30: =AH7 -> 662 | AN30: =AI7 -> 959 | AO30: =(AI30/$AI$2)*100 -> 7.3548387 | AP30: =(AJ30/$AI$2)*100 -> 20.967742 | AQ30: =(AK30/$AI$2)*100 -> 32.967742 | AR30: =(AL30/$AI$2)*100 -> 15.225806 | AS30: =(AM30/$AI$2)*100 -> 42.709677 | AT30: =(AN30/$AI$2)*100 -> 61.870968
B31: Templates | C31: =G18 -> 105 | D31: =H18 -> 353 | E31: =I18 -> 404 | F31: =G7 -> 193 | G31: =H7 -> 461 | H31: =I7 -> 517 | I31: =(C31/$I$25)*100 -> 16.8 | J31: =(D31/$I$25)*100 -> 56.48 | K31: =(E31/$I$25)*100 -> 64.64 | L31: =(F31/$I$25)*100 -> 30.88 | M31: =(G31/$I$25)*100 -> 73.76 | N31: =(H31/$I$25)*100 -> 82.72 | R31: Templates | S31: =W18 -> 83 | T31: =X18 -> 340 | U31: =Y18 -> 407 | V31: =W7 -> 204 | W31: =X7 -> 524 | X31: =Y7 -> 630 | Y31: =(S31/$S$2)*100 -> 8.972973 | Z31: =(T31/$S$2)*100 -> 36.756757 | AA31: =(U31/$S$2)*100 -> 44 | AB31: =(V31/$S$2)*100 -> 22.054054 | AC31: =(W31/$S$2)*100 -> 56.648649 | AD31: =(X31/$S$2)*100 -> 68.108108 | AH31: Templates | AI31: =AM18 -> 188 | AJ31: =AN18 -> 693 | AK31: =AO18 -> 811 | AL31: =AM7 -> 397 | AM31: =AN7 -> 985 | AN31: =AO7 -> 1147 | AO31: =(AI31/$AI$2)*100 -> 12.129032 | AP31: =(AJ31/$AI$2)*100 -> 44.709677 | AQ31: =(AK31/$AI$2)*100 -> 52.322581 | AR31: =(AL31/$AI$2)*100 -> 25.612903 | AS31: =(AM31/$AI$2)*100 -> 63.548387 | AT31: =(AN31/$AI$2)*100 -> 74
A32: Semantic | B32: Alpha | C32: =D23 -> 2 | D32: =E23 -> 3 | E32: =F23 -> 4 | F32: =D12 -> 111 | G32: =E12 -> 201 | H32: =F12 -> 282 | I32: =(C32/$I$25)*100 -> 0.32 | J32: =(D32/$I$25)*100 -> 0.48 | K32: =(E32/$I$25)*100 -> 0.64 | L32: =(F32/$I$25)*100 -> 17.76 | M32: =(G32/$I$25)*100 -> 32.16 | N32: =(H32/$I$25)*100 -> 45.12 | Q32: Semantic-L | R32: Alpha | S32: =T23 -> 0 | T32: =U23 -> 0 | U32: =V23 -> 0 | V32: =T12 -> 142 | W32: =U12 -> 188 | X32: =V12 -> 363 | Y32: =(S32/$S$2)*100 -> 0 | Z32: =(T32/$S$2)*100 -> 0 | AA32: =(U32/$S$2)*100 -> 0 | AB32: =(V32/$S$2)*100 -> 15.351351 | AC32: =(W32/$S$2)*100 -> 20.324324 | AD32: =(X32/$S$2)*100 -> 39.243243 | AG32: Semantic | AH32: Alpha | AI32: =AJ23 -> 2 | AJ32: =AK23 -> 3 | AK32: =AL23 -> 4 | AL32: =AJ12 -> 253 | AM32: =AK12 -> 389 | AN32: =AL12 -> 645 | AO32: =(AI32/$AI$2)*100 -> 0.12903226 | AP32: =(AJ32/$AI$2)*100 -> 0.19354839 | AQ32: =(AK32/$AI$2)*100 -> 0.25806452 | AR32: =(AL32/$AI$2)*100 -> 16.322581 | AS32: =(AM32/$AI$2)*100 -> 25.096774 | AT32: =(AN32/$AI$2)*100 -> 41.612903
B33: Length | C33: =A23 -> 43 | D33: =B23 -> 159 | E33: =C23 -> 319 | F33: =A12 -> 131 | G33: =B12 -> 315 | H33: =C12 -> 474 | I33: =(C33/$I$25)*100 -> 6.88 | J33: =(D33/$I$25)*100 -> 25.44 | K33: =(E33/$I$25)*100 -> 51.04 | L33: =(F33/$I$25)*100 -> 20.96 | M33: =(G33/$I$25)*100 -> 50.4 | N33: =(H33/$I$25)*100 -> 75.84 | R33: Length | S33: =Q23 -> 133 | T33: =R23 -> 213 | U33: =S23 -> 327 | V33: =Q12 -> 143 | W33: =R12 -> 419 | X33: =S12 -> 518 | Y33: =(S33/$S$2)*100 -> 14.378378 | Z33: =(T33/$S$2)*100 -> 23.027027 | AA33: =(U33/$S$2)*100 -> 35.351351 | AB33: =(V33/$S$2)*100 -> 15.459459 | AC33: =(W33/$S$2)*100 -> 45.297297 | AD33: =(X33/$S$2)*100 -> 56 | AH33: Length | AI33: =AG23 -> 176 | AJ33: =AH23 -> 372 | AK33: =AI23 -> 646 | AL33: =AG12 -> 274 | AM33: =AH12 -> 734 | AN33: =AI12 -> 992 | AO33: =(AI33/$AI$2)*100 -> 11.354839 | AP33: =(AJ33/$AI$2)*100 -> 24 | AQ33: =(AK33/$AI$2)*100 -> 41.677419 | AR33: =(AL33/$AI$2)*100 -> 17.677419 | AS33: =(AM33/$AI$2)*100 -> 47.354839 | AT33: =(AN33/$AI$2)*100 -> 64
B34: Templates | C34: =G23 -> 340 | D34: =H23 -> 510 | E34: =I23 -> 542 | F34: =G12 -> 398 | G34: =H12 -> 540 | H34: =I12 -> 562 | I34: =(C34/$I$25)*100 -> 54.4 | J34: =(D34/$I$25)*100 -> 81.6 | K34: =(E34/$I$25)*100 -> 86.72 | L34: =(F34/$I$25)*100 -> 63.68 | M34: =(G34/$I$25)*100 -> 86.4 | N34: =(H34/$I$25)*100 -> 89.92 | R34: Templates | S34: =W23 -> 290 | T34: =X23 -> 528 | U34: =Y23 -> 588 | V34: =W12 -> 464 | W34: =X12 -> 679 | X34: =Y12 -> 738 | Y34: =(S34/$S$2)*100 -> 31.351351 | Z34: =(T34/$S$2)*100 -> 57.081081 | AA34: =(U34/$S$2)*100 -> 63.567568 | AB34: =(V34/$S$2)*100 -> 50.162162 | AC34: =(W34/$S$2)*100 -> 73.405405 | AD34: =(X34/$S$2)*100 -> 79.783784 | AH34: Templates | AI34: =AM23 -> 630 | AJ34: =AN23 -> 1038 | AK34: =AO23 -> 1130 | AL34: =AM12 -> 862 | AM34: =AN12 -> 1219 | AN34: =AO12 -> 1300 | AO34: =(AI34/$AI$2)*100 -> 40.645161 | AP34: =(AJ34/$AI$2)*100 -> 66.967742 | AQ34: =(AK34/$AI$2)*100 -> 72.903226 | AR34: =(AL34/$AI$2)*100 -> 55.612903 | AS34: =(AM34/$AI$2)*100 -> 78.645161 | AT34: =(AN34/$AI$2)*100 -> 83.870968
C37: Template Improvement Over Other Rankings | S37: Template Improvement Over Other Rankings | AI37: Template Improvement Over Other Rankings
A39: Strat. | B39: Corr. | C39: Generator | F39: Completion Suggestions | Q39: Strat. | R39: Corr. | S39: Generator | V39: Completion Suggestions | AG39: Strat. | AH39: Corr. | AI39: Generator | AL39: Completion Suggestions
C40: Top 1 | D40: Top 5 | E40: Top 10 | F40: Top 1 | G40: Top 5 | H40: Top 10 | S40: Top 1 | T40: Top 5 | U40: Top 10 | V40: Top 1 | W40: Top 5 | X40: Top 10 | AI40: Top 1 | AJ40: Top 5 | AK40: Top 10 | AL40: Top 1 | AM40: Top 5 | AN40: Top 10
A41: Alpha | B41: Syntatic | E41: =(E31-E29/E29)*100 -> 40300 | F41: =(F31-F29/F29)*100 -> 19200 | G41: =(G31-G29/G29)*100 -> 46000 | H41: =(H31-H29/H29)*100 -> 51600 | Q41: Alpha | R41: Syntatic | V41: =(V31-V29/V29)*100 -> 20300 | W41: =(W31-W29/W29)*100 -> 52300 | X41: =(X31-X29/X29)*100 -> 62900 | AG41: Alpha | AH41: Syn | AK41: =(AK31-AK29/AK29)*100 -> 81000 | AL41: =(AL31-AL29/AL29)*100 -> 39600 | AM41: =(AM31-AM29/AM29)*100 -> 98400 | AN41: =(AN31-AN29/AN29)*100 -> 114600
B42: Semantic | E42: =(E34-E32)/E32*100 -> 13450 | F42: =(F34-F32)/F32*100 -> 258.55856 | G42: =(G34-G32)/G32*100 -> 168.65672 | H42: =(H34-H32)/H32*100 -> 99.29078 | R42: Semantic | V42: =(V34-V32)/V32*100 -> 226.76056 | W42: =(W34-W32)/W32*100 -> 261.17021 | X42: =(X34-X32)/X32*100 -> 103.30579 | AH42: Sem | AI42: =(AI34-AI32)/AI32*100 -> 31400 | AJ42: =(AJ34-AJ32)/AJ32*100 -> 34500 | AK42: =(AK34-AK32)/AK32*100 -> 28150 | AL42: =(AL34-AL32)/AL32*100 -> 240.71146 | AM42: =(AM34-AM32)/AM32*100 -> 213.36761 | AN42: =(AN34-AN32)/AN32*100 -> 101.55039
A43: Length | B43: Syntatic | C43: =(C31-C30)/C30*100 -> 238.70968 | D43: =(D31-D30)/D30*100 -> 218.01802 | E43: =(E31-E30)/E30*100 -> 65.57377 | F43: =(F31-F30)/F30*100 -> 98.969072 | G43: =(G31-G30)/G30*100 -> 70.740741 | H43: =(H31-H30)/H30*100 -> 14.888889 | Q43: Length | R43: Syntatic | S43: =(S31-S30)/S30*100 -> 0 | T43: =(T31-T30)/T30*100 -> 58.878505 | U43: =(U31-U30)/U30*100 -> 52.434457 | V43: =(V31-V30)/V30*100 -> 46.76259 | W43: =(W31-W30)/W30*100 -> 33.673469 | X43: =(X31-X30)/X30*100 -> 23.772102 | AG43: Length | AH43: Syn | AI43: =(AI31-AI30)/AI30*100 -> 64.912281 | AJ43: =(AJ31-AJ30)/AJ30*100 -> 113.23077 | AK43: =(AK31-AK30)/AK30*100 -> 58.708415 | AL43: =(AL31-AL30)/AL30*100 -> 68.220339 | AM43: =(AM31-AM30)/AM30*100 -> 48.791541 | AN43: =(AN31-AN30)/AN30*100 -> 19.603754
B44: Semantic | C44: =(C34-C33)/C33*100 -> 690.69767 | D44: =(D34-D33)/D33*100 -> 220.75472 | E44: =(E34-E33)/E33*100 -> 69.905956 | F44: =(F34-F33)/F33*100 -> 203.81679 | G44: =(G34-G33)/G33*100 -> 71.428571 | H44: =(H34-H33)/H33*100 -> 18.565401 | R44: Semantic | S44: =(S34-S33)/S33*100 -> 118.04511 | T44: =(T34-T33)/T33*100 -> 147.88732 | U44: =(U34-U33)/U33*100 -> 79.816514 | V44: =(V34-V33)/V33*100 -> 224.47552 | W44: =(W34-W33)/W33*100 -> 62.052506 | X44: =(X34-X33)/X33*100 -> 42.471042 | AH44: Sem | AI44: =(AI34-AI33)/AI33*100 -> 257.95455 | AJ44: =(AJ34-AJ33)/AJ33*100 -> 179.03226 | AK44: =(AK34-AK33)/AK33*100 -> 74.922601 | AL44: =(AL34-AL33)/AL33*100 -> 214.59854 | AM44: =(AM34-AM33)/AM33*100 -> 66.076294 | AN44: =(AN34-AN33)/AN33*100 -> 31.048387
C47: Completion improvements over generator | S47: Completion improvements over generator | AI47: Completion improvements over generator
A49: Strat. | B49: Corr. | C49: Top 1 | D49: Top 5 | E49: Top 10 | Q49: Strat. | R49: Corr. | S49: Top 1 | T49: Top 5 | U49: Top 10 | AG49: Strat. | AH49: Corr. | AI49: Top 1 | AJ49: Top 5 | AK49: Top 10
A50: Alpha | B50: Syntatic | E50: =(H29-E29)/E29*100 -> 26600 | Q50: Alpha | R50: Syntatic | AG50: Alpha | AH50: Syntatic | AI50: =(AL29-AI29)/AI29*100 -> #DIV/0! | AJ50: =(AM29-AJ29)/AJ29*100 -> #DIV/0! | AK50: =(AN29-AK29)/AK29*100 -> 52500
...

Sheet accuracy details
A1: model | B1: # exact | C1: loc exact | D1: start | E1: loc start | F1: loc start or match | G1: # sem | H1: loc sem | I1: total sug | J1: % valid | L1: model | M1: # exact | N1: loc exact | O1: start | P1: loc start | Q1: loc start or match | R1: # sem | S1: loc sem | T1: total sug | U1: % valid
A2: array | B2: 9 | C2: 9 | D2: 2 | E2: 2 | F2: 9 | G2: 28 | H2: 9 | I2: 54 | J2: =G2/I2*100 -> 51.851852 | L2: array | M2: 7 | N2: 7 | O2: 2 | P2: 2 | Q2: 9 | R2: 70 | S2: 9 | T2: 546 | U2: =R2/T2*100 -> 12.820513
A3: bempl | B3: 8 | C3: 8 | D3: 2 | E3: 2 | F3: 8 | G3: 21 | H3: 8 | I3: 222 | J3: =G3/I3*100 -> 9.4594595 | L3: bempl | M3: 6 | N3: 6 | O3: 2 | P3: 2 | Q3: 8 | R3: 32 | S3: 7 | T3: 887 | U3: =R3/T3*100 -> 3.6076663
A4: binary-tree | B4: 9 | C4: 9 | D4: 1 | E4: 1 | F4: 9 | G4: 688 | H4: 9 | I4: 1212 | J4: =G4/I4*100 -> 56.765677 | L4: binary-tree | M4: 6 | N4: 6 | O4: 1 | P4: 1 | Q4: 9 | R4: 1136 | S4: 9 | T4: 2970 | U4: =R4/T4*100 -> 38.249158
A5: class-diagram | B5: 4 | C5: 4 | D5: 1 | E5: 1 | F5: 6 | G5: 121 | H5: 6 | I5: 170 | J5: =G5/I5*100 -> 71.176471 | L5: class-diagram | M5: 3 | N5: 3 | O5: 1 | P5: 1 | Q5: 6 | R5: 147 | S5: 6 | T5: 425 | U5: =R5/T5*100 -> 34.588235
A6: classroom | B6: 29 | C6: 29 | D6: 3 | E6: 3 | F6: 30 | G6: 1760 | H6: 29 | I6: 2169 | J6: =G6/I6*100 -> 81.143384 | L6: classroom | M6: 20 | N6: 20 | O6: 11 | P6: 10 | Q6: 29 | R6: 4854 | S6: 28 | T6: 11988 | U6: =R6/T6*100 -> 40.49049
A7: classroom-fol | B7: 34 | C7: 34 | D7: 4 | E7: 4 | F7: 37 | G7: 2290 | H7: 35 | I7: 2672 | J7: =G7/I7*100 -> 85.703593 | L7: classroom-fol | M7: 26 | N7: 26 | O7: 12 | P7: 11 | Q7: 36 | R7: 4013 | S7: 34 | T7: 9821 | U7: =R7/T7*100 -> 40.861419
A8: classroom-rl | B8: 27 | C8: 27 | D8: 2 | E8: 2 | F8: 28 | G8: 1686 | H8: 28 | I8: 1974 | J8: =G8/I8*100 -> 85.410334 | L8: classroom-rl | M8: 24 | N8: 24 | O8: 8 | P8: 8 | Q8: 28 | R8: 3052 | S8: 28 | T8: 6907 | U8: =R8/T8*100 -> 44.187057
A9: courses-v1 | B9: 42 | C9: 42 | D9: 8 | E9: 8 | F9: 47 | G9: 1106 | H9: 44 | I9: 2221 | J9: =G9/I9*100 -> 49.797389 | L9: courses-v1 | M9: 35 | N9: 35 | O9: 20 | P9: 19 | Q9: 51 | R9: 4601 | S9: 45 | T9: 32116 | U9: =R9/T9*100 -> 14.326193
A10: courses-v2 | B10: 58 | C10: 58 | D10: 6 | E10: 6 | F10: 59 | G10: 1588 | H10: 58 | I10: 2680 | J10: =G10/I10*100 -> 59.253731 | L10: courses-v2 | M10: 38 | N10: 38 | O10: 32 | P10: 31 | Q10: 62 | R10: 7673 | S10: 59 | T10: 42101 | U10: =R10/T10*100 -> 18.22522
A11: c-tree | B11: 7 | C11: 7 | D11: 3 | E11: 3 | F11: 8 | G11: 395 | H11: 7 | I11: 657 | J11: =G11/I11*100 -> 60.121766 | L11: c-tree | M11: 4 | N11: 4 | O11: 2 | P11: 2 | Q11: 8 | R11: 436 | S11: 7 | T11: 1589 | U11: =R11/T11*100 -> 27.438641
A12: cv | B12: 16 | C12: 16 | D12: 6 | E12: 6 | F12: 20 | G12: 517 | H12: 19 | I12: 1061 | J12: =G12/I12*100 -> 48.727615 | L12: cv | M12: 14 | N12: 14 | O12: 6 | P12: 6 | Q12: 22 | R12: 897 | S12: 21 | T12: 7923 | U12: =R12/T12*100 -> 11.321469
A13: dll | B13: 9 | C13: 9 | D13: 2 | E13: 2 | F13: 9 | G13: 277 | H13: 9 | I13: 708 | J13: =G13/I13*100 -> 39.124294 | L13: dll | M13: 5 | N13: 5 | O13: 4 | P13: 3 | Q13: 9 | R13: 1175 | S13: 9 | T13: 4614 | U13: =R13/T13*100 -> 25.465973
... A34: modelo-alloy | B34: 80 | C34: 80 | D34: 65 | E34: 54 | F34: 97 | G34: 172514 | H34: 80 | I34: 217845 | J34: =G34/I34*100 -> 79.191168 | L34: modelo-alloy | M34: 54 | N34: 54 | O34: 43 | P34: 38 | Q34: 93 | R34: 42213 | S34: 75 | T34: 183396 | U34: =R34/T34*100 -> 23.017405
B35: =SUM(B2:B34) -> 1314 | C35: =SUM(C2:C34) -> 1314 | D35: =SUM(D2:D34) -> 678 | E35: =SUM(E2:E34) -> 530 | F35: =SUM(F2:F34) -> 1473 | G35: =SUM(G2:G34) -> 545938 | H35: =SUM(H2:H34) -> 1361 | I35: =SUM(I2:I34) -> 986923 | J35: =G35/I35*100 -> 55.317183 | M35: =SUM(M2:M34) -> 1032 | N35: =SUM(N2:N34) -> 1032 | O35: =SUM(O2:O34) -> 571 | P35: =SUM(P2:P34) -> 538 | Q35: =SUM(Q2:Q34) -> 1483 | R35: =SUM(R2:R34) -> 246152 | S35: =SUM(S2:S34) -> 1324 | T35: =SUM(T2:T34) -> 1295522 | U35: =R35/T35*100 -> 19.000218
A37: Model | B37: # Loc | C37: Formula Completions | G37: Generator
C38: Locations With | F38: % Valid | H38: Locations With | J38: % Valid
C39: Syn | D39: Sem | E39: Start + | G39: Syn | H39: Sem | I39: Start +
A40: array | B40: 9 | C40: =B2 -> 9 | D40: =H2 -> 9 | E40: =F2 -> 9 | F40: =J2 -> 51.851852 | G40: =M2 -> 7 | H40: =S2 -> 9 | I40: =Q2 -> 9 | J40: =U2 -> 12.820513
A41: bempl | B41: 8 | C41: =B3 -> 8 | D41: =H3 -> 8 | E41: =F3 -> 8 | F41: =J3 -> 9.4594595 | G41: =M3 -> 6 | H41: =S3 -> 7 | I41: =Q3 -> 8 | J41: =U3 -> 3.6076663
A42: binary-tree | B42: 9 | C42: =B4 -> 9 | D42: =H4 -> 9 | E42: =F4 -> 9 | F42: =J4 -> 56.765677 | G42: =M4 -> 6 | H42: =S4 -> 9 | I42: =Q4 -> 9 | J42: =U4 -> 38.249158
A43: c-tree | B43: 9 | C43: =B11 -> 7 | D43: =H11 -> 7 | E43: =F11 -> 8 | F43: =J11 -> 60.121766 | G43: =M11 -> 4 | H43: =S11 -> 7 | I43: =Q11 -> 8 | J43: =U4 -> 38.249158
A44: class-diagram | B44: 6 | C44: =B5 -> 4 | D44: =H5 -> 6 | E44: =F5 -> 6 | F44: =J5 -> 71.176471 | G44: =M5 -> 3 | H44: =S5 -> 6 | I44: =Q5 -> 6 | J44: =U11 -> 27.438641
A45: classroom | B45: 30 | C45: =B6 -> 29 | D45: =H6 -> 29 | E45: =F6 -> 30 | F45: =J6 -> 81.143384 | G45: =M6 -> 20 | H45: =S6 -> 28 | I45: =Q6 -> 29 | J45: =U6 -> 40.49049
A46: classroom-fol | B46: 38 | C46: =B7 -> 34 | D46: =H7 -> 35 | E46: =F7 -> 37 | F46: =J7 -> 85.703593 | G46: =M7 -> 26 | H46: =S7 -> 34 | I46: =Q7 -> 36 | J46: =U7 -> 40.861419
A47: classroom-rl | B47: 30 | C47: =B8 -> 27 | D47: =H8 -> 28 | E47: =F8 -> 28 | F47: =J8 -> 85.410334 | G47: =M8 -> 24 | H47: =S8 -> 28 | I47: =Q8 -> 28 | J47: =U8 -> 44.187057
A48: courses-v1 | B48: 55 | C48: =B9 -> 42 | D48: =H9 -> 44 | E48: =F9 -> 47 | F48: =J9 -> 49.797389 | G48: =M9 -> 35 | H48: =S9 -> 45 | I48: =Q9 -> 51 | J48: =U9 -> 14.326193
A49: courses-v2 | B49: 67 | C49: =B10 -> 58 | D49: =H10 -> 58 | E49: =F10 -> 59 | F49: =J10 -> 59.253731 | G49: =M10 -> 38 | H49: =S10 -> 59 | I49: =Q10 -> 62 | J49: =U10 -> 18.22522
A50: cv | B50: 24 | C50: =B12 -> 16 | D50: =H12 -> 19 | E50: =F12 -> 20 | F50: =J12 -> 48.727615 | G50: =M12 -> 14 | H50: =S12 -> 21 | I50: =Q12 -> 22 | J50: =U12 -> 11.321469
A51: dll | B51: 9 | C51: =B13 -> 9 | D51: =H13 -> 9 | E51: =F13 -> 9 | F51: =J13 -> 39.124294 | G51: =M13 -> 5 | H51: =S13 -> 9 | I51: =Q13 -> 9 | J51: =U13 -> 25.465973
A52: fsm | B52: 15 | C52: =B14 -> 14 | D52: =H14 -> 15 | E52: =F14 -> 15 | F52: =J14 -> 34.683544 | G52: =M14 -> 7 | H52: =S14 -> 15 | I52: =Q14 -> 15 | J52: =U14 -> 17.50646
A53: grade | B53: 10 | C53: =B15 -> 10 | D53: =H15 -> 10 | E53: =F15 -> 10 | F53: =J15 -> 91.59292 | G53: =M15 -> 7 | H53: =S15 -> 10 | I53: =Q15 -> 10 | J53: =U15 -> 32.45614
A54: graph | B54: 8 | C54: =B16 -> 7 | D54: =H16 -> 8 | E54: =F16 -> 8 | F54: =J16 -> 69.325153 | G54: =M16 -> 1 | H54: =S16 -> 8 | I54: =Q16 -> 8 | J54: =U16 -> 35.714286
A55: handshake | B55: 20 | C55: =B17 -> 19 | D55: =H17 -> 19 | E55: =F17 -> 20 | F55: =J17 -> 52.57286 | G55: =M17 -> 15 | H55: =S17 -> 20 | I55: =Q17 -> 20 | J55: =U17 -> 22.731255
A56: lts | B56: 18 | C56: =B18 -> 14 | D56: =H18 -> 14 | E56: =F18 -> 14 | F56: =J18 -> 75.123153 | G56: =M18 -> 9 | H56: =S18 -> 14 | I56: =Q18 -> 14 | J56: =U18 -> 21.789657
A57: nqueens | B57: 16 | C57: =B19 -> 8 | D57: =H19 -> 8 | E57: =F19 -> 16 | F57: =J19 -> 12.5 | G57: =M19 -> 8 | H57: =S19 -> 8 | I57: =Q19 -> 16 | J57: =U19 -> 0.60790274
A58: production-line-v1 | B58: 12 | C58: =B20 -> 9 | D58: =H20 -> 10 | E58: =F20 -> 12 | F58: =J20 -> 29.319372 | G58: =M20 -> 7 | H58: =S20 -> 10 | I58: =Q20 -> 12 | J58: =U20 -> 9.4838439
A59: production-line-v2 | B59: 34 | C59: =B21 -> 29 | D59: =H21 -> 31 | E59: =F21 -> 31 | F59: =J21 -> 64.305402 | G59: =M21 -> 26 | H59: =S21 -> 33 | I59: =Q21 -> 33 | J59: =U21 -> 24.517421
A60: production-line-v3 | B60: 36 | C60: =B22 -> 31 | D60: =H22 -> 33 | E60: =F22 -> 35 | F60: =J22 -> 73.366714 | G60: =M22 -> 27 | H60: =S22 -> 34 | I60: =Q22 -> 36 | J60: =U22 -> 32.547064
A61: singly-linked-list | B61: 4 | C61: =B23 -> 4 | D61: =H23 -> 4 | E61: =F23 -> 4 | F61: =J23 -> 37.313433 | G61: =M23 -> 2 | H61: =S23 -> 4 | I61: =Q23 -> 4 | J61: =U23 -> 18.901099
...

Sheet performance
A1: model | B1: #loc | C1: #gen | D1: #form | E1: r | F1: #g/l | G1: #f/l | H1: r | I1: gen t | J1: form t | K1: r
A2: array | B2: 9 | C2: 546 | D2: 54 | E2: =(C2-D2)/C2*100 -> 90.10989 | F2: 61 | G2: 6 | H2: 90 | I2: 60 | J2: 51 | K2: 9
A3: bempl | B3: 8 | C3: 887 | D3: 222 | E3: =(C3-D3)/C3*100 -> 74.971815 | F3: 111 | G3: 28 | H3: 75 | I3: 18 | J3: 31 | K3: -13
A4: binary-tree | B4: 9 | C4: 2970 | D4: 1212 | E4: =(C4-D4)/C4*100 -> 59.191919 | F4: 330 | G4: 135 | H4: 59 | I4: 22 | J4: 30 | K4: -8
A5: c-tree | B5: 9 | C5: 1589 | D5: 657 | E5: =(C5-D5)/C5*100 -> 58.653241 | F5: 177 | G5: 73 | H5: 59 | I5: 15 | J5: 15 | K5: 0
A6: class-diagram | B6: 6 | C6: 425 | D6: 170 | E6: =(C6-D6)/C6*100 -> 60 | F6: 71 | G6: 28 | H6: 60 | I6: 17 | J6: 14 | K6: 3
A7: classroom | B7: 30 | C7: 11988 | D7: 2040 | E7: =(C7-D7)/C7*100 -> 82.982983 | F7: 400 | G7: 68 | H7: 83 | I7: 21 | J7: 20 | K7: 1
A8: classroom-fol | B8: 38 | C8: 9821 | D8: 2670 | E8: =(C8-D8)/C8*100 -> 72.813359 | F8: 258 | G8: 70 | H8: 73 | I8: 18 | J8: 21 | K8: -3
A9: classroom-rl | B9: 30 | C9: 6907 | D9: 1974 | E9: =(C9-D9)/C9*100 -> 71.420298 | F9: 230 | G9: 66 | H9: 71 | I9: 16 | J9: 16 | K9: 0
A10: courses-v1 | B10: 55 | C10: 32116 | D10: 2318 | E10: =(C10-D10)/C10*100 -> 92.782414 | F10: 584 | G10: 42 | H10: 93 | I10: 28 | J10: 25 | K10: 3
A11: courses-v2 | B11: 67 | C11: 42101 | D11: 2794 | E11: =(C11-D11)/C11*100 -> 93.363578 | F11: 628 | G11: 42 | H11: 93 | I11: 30 | J11: 27 | K11: 3
A12: cv | B12: 24 | C12: 7923 | D12: 1061 | E12: =(C12-D12)/C12*100 -> 86.608608 | F12: 330 | G12: 44 | H12: 87 | I12: 16 | J12: 14 | K12: 2
A13: dll | B13: 9 | C13: 4614 | D13: 708 | E13: =(C13-D13)/C13*100 -> 84.655397 | F13: 513 | G13: 79 | H13: 85 | I13: 17 | J13: 11 | K13: 6
... A29: trash-rl | B29: 12 | C29: 2112 | D29: 616 | E29: =(C29-D29)/C29*100 -> 70.833333 | F29: 176 | G29: 51 | H29: 71 | I29: 12 | J29: 10 | K29: 2
A30: frank | B30: 89 | C30: 76621 | D30: 22724 | E30: =(C30-D30)/C30*100 -> 70.342334 | F30: =C30/B30 -> 860.91011 | G30: =D30/B30 -> 255.32584 | H30: =(F30-G30)/F30*100 -> 70.342334 | I30: 50 | J30: 66 | K30: -16
A31: git | B31: 365 | C31: 432360 | D31: 473085 | E31: =(C31-D31)/C31*100 -> -9.419234 | F31: =C31/B31 -> 1184.5479 | G31: =D31/B31 -> 1296.1233 | H31: =(F31-G31)/F31*100 -> -9.419234 | I31: 74 | J31: 175 | K31: -101
A32: icd | B32: 111 | C32: 88094 | D32: 8617 | E32: =(C32-D32)/C32*100 -> 90.218403 | F32: =C32/B32 -> 793.63964 | G32: =D32/B32 -> 77.630631 | H32: =(F32-G32)/F32*100 -> 90.218403 | I32: 36 | J32: 48 | K32: -11
A33: java-meta | B33: 261 | C33: 288390 | D33: 210408 | E33: =(C33-D33)/C33*100 -> 27.040466 | F33: =C33/B33 -> 1104.9425 | G33: =D33/B33 -> 806.16092 | H33: =(F33-G33)/F33*100 -> 27.040466 | I33: 70 | J33: 137 | K33: -66
A34: pet-tracker | B34: 99 | C34: 201245 | D34: 217845 | E34: =(C34-D34)/C34*100 -> -8.2486521 | F34: =C34/B34 -> 2032.7778 | G34: =D34/B34 -> 2200.4545 | H34: =(F34-G34)/F34*100 -> -8.2486521 | I34: 69 | J34: 196 | K34: -127
A35: Total | B35: =SUM(B2:B34) -> 1550 | C35: =SUM(C2:C34) -> 1341123 | D35: =SUM(D2:D34) -> 987003 | E35: =(C35-D35)/C35*100 -> 26.404737 | F35: =C35/B35 -> 865.24065 | G35: =D35/B35 -> 636.77613 | H35: =(F35-G35)/F35*100 -> 26.404737 | I35: 25 | J35: 36 | K35: -10

Sheet formula - syn -len-alpha
A1: i2e | B1: 1 | C1: 2 | D1: 1 | E1: 1 | F1: 1 | G1: TRUE | H1: TRUE | I1: TRUE | K1: top 1 | L1: top 5 | M1: top 10 | N1: top 1 | O1: top 5 | P1: top 10 | Q1: top 1 | R1: top 5 | S1: top 10 | T1: top 1 | U1: top 5 | V1: top 10
A2: length | B2: 2 | C2: 4 | D2: 4 | E2: 2 | F2: 1 | G2: TRUE | H2: TRUE | I2: TRUE | K2: =COUNTIF(B1:B1000,"=1") -> 193 | L2: =COUNTIF(B1:B1000,"<=5") -> 461 | M2: =COUNTIF(B1:B1000,"<=10") -> 517 | N2: =COUNTIF(C1:C1000,"=1") -> 71 | O2: =COUNTIF(C1:C1000,"<=5") -> 186 | P2: =COUNTIF(C1:C1000,"<=10") -> 250 | Q2: =COUNTIF(D1:D1000,"=1") -> 86 | R2: =COUNTIF(D1:D1000,"<=5") -> 172 | S2: =COUNTIF(D1:D1000,"<=10") -> 267 | T2: =COUNTIF(E1:E1000,"=1") -> 97 | U2: =COUNTIF(E1:E1000,"<=5") -> 270 | V2: =COUNTIF(E1:E1000,"<=10") -> 450 | X2: =COUNTIF(F1:F1000,"=1") -> 297
A3: i2e.Element | B3: 4 | C3: 1 | D3: 2 | E3: 5 | F3: 200021 | G3: TRUE | H3: TRUE | I3: TRUE
A4: Element | B4: 1 | C4: 1 | D4: 1 | E4: 2 | F4: 3 | G4: TRUE | H4: TRUE | I4: TRUE
A5: length | B5: 2 | C5: 5 | D5: 4 | E5: 2 | F5: 1 | G5: TRUE | H5: TRUE | I5: TRUE
A6: i2e.Element | B6: 4 | C6: 1 | D6: 2 | E6: 5 | F6: 200021 | G6: TRUE | H6: TRUE | I6: TRUE
A7: Element | B7: 1 | C7: 1 | D7: 1 | E7: 2 | F7: 3 | G7: TRUE | H7: TRUE | I7: TRUE
A8: i2e | B8: 1 | C8: 3 | D8: 1 | E8: 1 | F8: 1 | G8: TRUE | H8: TRUE | I8: TRUE
A9: Element | B9: 2 | C9: 2 | D9: 2 | E9: 6 | F9: 1 | G9: TRUE | H9: TRUE | I9: TRUE
A10: opened_by | B10: 2 | C10: 11 | D10: 4 | E10: 6 | F10: 2 | G10: TRUE | H10: TRUE | I10: TRUE
A11: p.owns.opened_by | B11: 8 | C11: 3 | D11: 35 | E11: 21 | F11: 5 | G11: TRUE | H11: TRUE | I11: TRUE
A12: owns.opened_by | B12: 3 | C12: 4 | D12: 4 | E12: 4 | F12: 11 | G12: TRUE | H12: TRUE | I12: TRUE
A13: Room | B13: 5 | C13: 5 | D13: 6 | E13: 3 | F13: 1 | G13: TRUE | H13: TRUE | I13: TRUE
A14: owns | B14: 1 | C14: 3 | D14: 1 | E14: 3 | F14: 1 | G14: TRUE | H14: TRUE | I14: TRUE
... A547: File | B547: 1 | C547: 1 | D547: 1 | E547: 2 | F547: 2 | G547: TRUE | H547: TRUE | I547: TRUE

Sheet formula first - length - alpha
A1: i2e | B1: 1 | C1: 2 | D1: 1 | E1: 1 | F1: 1 | G1: TRUE | H1: TRUE | I1: TRUE | K1: top 1 | L1: top 5 | M1: top 10 | N1: top 1 | O1: top 5 | P1: top 10 | Q1: top 1 | R1: top 5 | S1: top 10 | T1: top 1 | U1: top 5 | V1: top 10
A2: length | B2: 2 | C2: 4 | D2: 4 | E2: 2 | F2: 1 | G2: TRUE | H2: TRUE | I2: TRUE | K2: =COUNTIF(B1:B1000,"=1") -> 398 | L2: =COUNTIF(B1:B1000,"<=5") -> 540 | M2: =COUNTIF(B1:B1000,"<=10") -> 562 | N2: =COUNTIF(C1:C1000,"=1") -> 79 | O2: =COUNTIF(C1:C1000,"<=5") -> 200 | P2: =COUNTIF(C1:C1000,"<=10") -> 274 | Q2: =COUNTIF(D1:D1000,"=1") -> 111 | R2: =COUNTIF(D1:D1000,"<=5") -> 201 | S2: =COUNTIF(D1:D1000,"<=10") -> 282 | T2: =COUNTIF(E1:E1000,"=1") -> 131 | U2: =COUNTIF(E1:E1000,"<=5") -> 315 | V2: =COUNTIF(E1:E1000,"<=10") -> 474 | X2: =COUNTIF(F1:F1000,"=1") -> 405
A3: i2e.Element | B3: 4 | C3: 1 | D3: 2 | E3: 5 | F3: 200021 | G3: TRUE | H3: TRUE | I3: TRUE
A4: Element | B4: 1 | C4: 1 | D4: 1 | E4: 2 | F4: 3 | G4: TRUE | H4: TRUE | I4: TRUE
A5: length | B5: 2 | C5: 5 | D5: 4 | E5: 2 | F5: 1 | G5: TRUE | H5: TRUE | I5: TRUE
A6: i2e.Element | B6: 4 | C6: 1 | D6: 2 | E6: 5 | F6: 200021 | G6: TRUE | H6: TRUE | I6: TRUE
A7: Element | B7: 1 | C7: 1 | D7: 1 | E7: 2 | F7: 3 | G7: TRUE | H7: TRUE | I7: TRUE
A8: i2e | B8: 1 | C8: 3 | D8: 1 | E8: 1 | F8: 1 | G8: TRUE | H8: TRUE | I8: TRUE
A9: Element | B9: 2 | C9: 2 | D9: 2 | E9: 6 | F9: 1 | G9: TRUE | H9: TRUE | I9: TRUE
A10: opened_by | B10: 2 | C10: 11 | D10: 4 | E10: 6 | F10: 2 | G10: TRUE | H10: TRUE | I10: TRUE
A11: p.owns.opened_by | B11: 8 | C11: 3 | D11: 35 | E11: 21 | F11: 5 | G11: TRUE | H11: TRUE | I11: TRUE
A12: owns.opened_by | B12: 3 | C12: 4 | D12: 4 | E12: 4 | F12: 11 | G12: TRUE | H12: TRUE | I12: TRUE
A13: Room | B13: 5 | C13: 5 | D13: 6 | E13: 3 | F13: 1 | G13: TRUE | H13: TRUE | I13: TRUE
A14: owns | B14: 1 | C14: 3 | D14: 1 | E14: 3 | F14: 1 | G14: TRUE | H14: TRUE | I14: TRUE
... A568: File | B568: 1 | C568: 1 | D568: 1 | E568: 2 | F568: 2 | G568: TRUE | H568: TRUE | I568: TRUE

Sheet gen - syn - len alpha
A1: i2e | B1: 1 | C1: 55 | D1: 57 | E1: 2 | F1: 1 | G1: TRUE | H1: TRUE | I1: TRUE | K1: top 1 | L1: top 5 | M1: top 10 | N1: top 1 | O1: top 5 | P1: top 10 | Q1: top 1 | R1: top 5 | S1: top 10 | T1: top 1 | U1: top 5 | V1: top 10
A2: length | B2: 2 | C2: 57 | D2: 58 | E2: 7 | F2: 1 | G2: TRUE | H2: TRUE | I2: TRUE | K2: =COUNTIF(B1:B1000,"=1") -> 105 | L2: =COUNTIF(B1:B1000,"<=5") -> 353 | M2: =COUNTIF(B1:B1000,"<=10") -> 404 | N2: =COUNTIF(C1:C1000,"=1") -> 0 | O2: =COUNTIF(C1:C1000,"<=5") -> 0 | P2: =COUNTIF(C1:C1000,"<=10") -> 1 | Q2: =COUNTIF(D1:D1000,"=1") -> 0 | R2: =COUNTIF(D1:D1000,"<=5") -> 0 | S2: =COUNTIF(D1:D1000,"<=10") -> 1 | T2: =COUNTIF(E1:E1000,"=1") -> 31 | U2: =COUNTIF(E1:E1000,"<=5") -> 111 | V2: =COUNTIF(E1:E1000,"<=10") -> 244
A3: Element | B3: 4 | C3: 54 | D3: 54 | E3: 8 | F3: 3 | G3: TRUE | H3: TRUE | I3: TRUE
A4: length | B4: 2 | C4: 77 | D4: 78 | E4: 8 | F4: 1 | G4: TRUE | H4: TRUE | I4: TRUE
A5: Element | B5: 4 | C5: 54 | D5: 54 | E5: 8 | F5: 3 | G5: TRUE | H5: TRUE | I5: TRUE
A6: i2e | B6: 1 | C6: 74 | D6: 76 | E6: 2 | F6: 1 | G6: TRUE | H6: TRUE | I6: TRUE
A7: Element | B7: 2 | C7: 21 | D7: 21 | E7: 7 | F7: 1 | G7: TRUE | H7: TRUE | I7: TRUE
A8: opened_by | B8: 4 | C8: 116 | D8: 120 | E8: 15 | F8: 2 | G8: TRUE | H8: TRUE | I8: TRUE
A9: Room | B9: 5 | C9: 87 | D9: 83 | E9: 3 | F9: 1 | G9: TRUE | H9: TRUE | I9: TRUE
A10: owns | B10: 3 | C10: 84 | D10: 88 | E10: 5 | F10: 1 | G10: TRUE | H10: TRUE | I10: TRUE
A11: Researcher | B11: 5 | C11: 104 | D11: 99 | E11: 16 | F11: 2 | G11: TRUE | H11: TRUE | I11: TRUE
A12: Person | B12: 3 | C12: 85 | D12: 81 | E12: 7 | F12: 1 | G12: TRUE | H12: TRUE | I12: TRUE
A13: Person | B13: 3 | C13: 131 | D13: 127 | E13: 7 | F13: 1 | G13: TRUE | H13: TRUE | I13: TRUE
A14: right | B14: 18 | C14: 328 | D14: 329 | E14: 7 | F14: 100021 | G14: TRUE | H14: TRUE | I14: TRUE
... A421: File | B421: 1 | C421: 85 | D421: 85 | E421: 2 | F421: 2 | G421: TRUE | H421: TRUE | I421: TRUE

Sheet gen - first - len - alpha
A1: i2e | B1: 1 | C1: 55 | D1: 57 | E1: 2 | F1: 1 | G1: TRUE | H1: TRUE | I1: TRUE | K1: top 1 | L1: top 5 | M1: top 10 | N1: top 1 | O1: top 5 | P1: top 10 | Q1: top 1 | R1: top 5 | S1: top 10 | T1: top 1 | U1: top 5 | V1: top 10
A2: length | B2: 2 | C2: 57 | D2: 58 | E2: 7 | F2: 1 | G2: TRUE | H2: TRUE | I2: TRUE | K2: =COUNTIF(B1:B1000,"=1") -> 340 | L2: =COUNTIF(B1:B1000,"<=5") -> 510 | M2: =COUNTIF(B1:B1000,"<=10") -> 542 | N2: =COUNTIF(C1:C1000,"=1") -> 2 | O2: =COUNTIF(C1:C1000,"<=5") -> 2 | P2: =COUNTIF(C1:C1000,"<=10") -> 4 | Q2: =COUNTIF(D1:D1000,"=1") -> 2 | R2: =COUNTIF(D1:D1000,"<=5") -> 3 | S2: =COUNTIF(D1:D1000,"<=10") -> 4 | T2: =COUNTIF(E1:E1000,"=1") -> 43 | U2: =COUNTIF(E1:E1000,"<=5") -> 159 | V2: =COUNTIF(E1:E1000,"<=10") -> 319
A3: ((i2e.Element)-length) | B3: 11 | C3: 1 | D3: 1 | E3: 54 | F3: 200021 | G3: FALSE | H3: FALSE | I3: TRUE
A4: Element | B4: 4 | C4: 54 | D4: 54 | E4: 8 | F4: 3 | G4: TRUE | H4: TRUE | I4: TRUE
A5: length | B5: 2 | C5: 77 | D5: 78 | E5: 8 | F5: 1 | G5: TRUE | H5: TRUE | I5: TRUE
A6: ((i2e.Element)-length) | B6: 11 | C6: 1 | D6: 1 | E6: 54 | F6: 200021 | G6: FALSE | H6: FALSE | I6: TRUE
A7: Element | B7: 4 | C7: 54 | D7: 54 | E7: 8 | F7: 3 | G7: TRUE | H7: TRUE | I7: TRUE
A8: i2e | B8: 1 | C8: 74 | D8: 76 | E8: 2 | F8: 1 | G8: TRUE | H8: TRUE | I8: TRUE
A9: Element | B9: 2 | C9: 21 | D9: 21 | E9: 7 | F9: 1 | G9: TRUE | H9: TRUE | I9: TRUE
A10: opened_by | B10: 4 | C10: 116 | D10: 120 | E10: 15 | F10: 2 | G10: TRUE | H10: TRUE | I10: TRUE
A11: (owns.opened_by) | B11: 23 | C11: 73 | D11: 82 | E11: 49 | F11: 11 | G11: FALSE | H11: FALSE | I11: TRUE
A12: Room | B12: 5 | C12: 87 | D12: 83 | E12: 3 | F12: 1 | G12: TRUE | H12: TRUE | I12: TRUE
A13: authorized | B13: 1 | C13: 78 | D13: 85 | E13: 14 | F13: 1 | G13: FALSE | H13: FALSE | I13: TRUE
A14: Researcher | B14: 5 | C14: 104 | D14: 99 | E14: 16 | F14: 2 | G14: TRUE | H14: TRUE | I14: TRUE
... A570: File | B570: 1 | C570: 85 | D570: 85 | E570: 2 | F570: 2 | G570: TRUE | H570: TRUE | I570: TRUE

Sheet formula - syn - large
A1: GeomagicTouch | B1: 19 | C1: 19 | D1: 19 | E1: 34 | F1: 1002 | G1: TRUE | H1: TRUE | I1: TRUE | K1: top 1 | L1: top 5 | M1: top 10 | N1: top 1 | O1: top 5 | P1: top 10 | Q1: top 1 | R1: top 5 | S1: top 10
A2: Robot | B2: 38 | C2: 38 | D2: 39 | E2: 7 | F2: 1002 | G2: TRUE | H2: TRUE | I2: TRUE | K2: =COUNTIF(B1:B1000,"=1") -> 204 | L2: =COUNTIF(B1:B1000,"<=5") -> 524 | M2: =COUNTIF(B1:B1000,"<=10") -> 630 | N2: =COUNTIF(D1:D1000,"=1") -> 75 | O2: =COUNTIF(D1:D1000,"<=5") -> 110 | P2: =COUNTIF(D1:D1000,"<=10") -> 259 | Q2: =COUNTIF(E1:E1000,"=1") -> 139 | R2: =COUNTIF(E1:E1000,"<=5") -> 392 | S2: =COUNTIF(E1:E1000,"<=10") -> 509 | X2: =COUNTIF(F1:F1000,"=1") -> 539 | Y2: =COUNTIF(F1:F1000,"=1") -> 539
A3: solverResult | B3: 1 | C3: 7 | D3: 1 | E3: 3 | F3: 1 | G3: TRUE | H3: TRUE | I3: TRUE
A4: output | B4: 1 | C4: 3 | D4: 1 | E4: 2 | F4: 100021 | G4: TRUE | H4: TRUE | I4: TRUE
A5: armModel | B5: 1 | C5: 15 | D5: 1 | E5: 4 | F5: 1 | G5: TRUE | H5: TRUE | I5: TRUE
A6: g.input | B6: 1 | C6: 2 | D6: 318 | E6: 3 | F6: 1 | G6: TRUE | H6: TRUE | I6: TRUE
A7: input | B7: 2 | C7: 9 | D7: 6 | E7: 6 | F7: 1 | G7: TRUE | H7: TRUE | I7: TRUE
A8: s.solverResult | B8: 1 | C8: 3 | D8: 27 | E8: 22 | F8: 1 | G8: TRUE | H8: TRUE | I8: TRUE
A9: solverResult | B9: 1 | C9: 8 | D9: 1 | E9: 3 | F9: 1 | G9: TRUE | H9: TRUE | I9: TRUE
A10: r.includes | B10: 1 | C10: 10 | D10: 608 | E10: 4 | F10: 1 | G10: TRUE | H10: TRUE | I10: TRUE
A11: includes | B11: 1 | C11: 16 | D11: 1 | E11: 3 | F11: 1 | G11: TRUE | H11: TRUE | I11: TRUE
A12: effectorType | B12: 3 | C12: 20 | D12: 12 | E12: 10 | F12: 100021 | G12: TRUE | H12: TRUE | I12: TRUE
A13: effectorType | B13: 3 | C13: 20 | D13: 12 | E13: 10 | F13: 100021 | G13: TRUE | H13: TRUE | I13: TRUE
A14: effectorType | B14: 3 | C14: 20 | D14: 12 | E14: 10 | F14: 100021 | G14: TRUE | H14: TRUE | I14: TRUE
... A767: Publication | B767: 26 | C767: 26 | D767: 27 | E767: 38 | F767: 1 | G767: TRUE | H767: TRUE | I767: TRUE

Sheet formula - first - large
A1: ArmAngle | B1: 1 | C1: 1 | D1: 1 | E1: 13 | F1: 1002 | G1: FALSE | H1: FALSE | I1: TRUE | K1: top 1 | L1: top 5 | M1: top 10 | N1: top 1 | O1: top 5 | P1: top 10 | Q1: top 1 | R1: top 5 | S1: top 10
A2: ArmAngle | B2: 1 | C2: 1 | D2: 1 | E2: 13 | F2: 1002 | G2: FALSE | H2: FALSE | I2: TRUE | K2: =COUNTIF(B1:B1000,"=1") -> 464 | L2: =COUNTIF(B1:B1000,"<=5") -> 679 | M2: =COUNTIF(B1:B1000,"<=10") -> 738 | N2: =COUNTIF(D1:D1000,"=1") -> 142 | O2: =COUNTIF(D1:D1000,"<=5") -> 188 | P2: =COUNTIF(D1:D1000,"<=10") -> 363 | Q2: =COUNTIF(E1:E1000,"=1") -> 143 | R2: =COUNTIF(E1:E1000,"<=5") -> 419 | S2: =COUNTIF(E1:E1000,"<=10") -> 518 | X2: =COUNTIF(F1:F1000,"=1") -> 633
A3: solverResult | B3: 1 | C3: 7 | D3: 1 | E3: 3 | F3: 1 | G3: TRUE | H3: TRUE | I3: TRUE
A4: output | B4: 1 | C4: 3 | D4: 1 | E4: 2 | F4: 100021 | G4: TRUE | H4: TRUE | I4: TRUE
A5: armModel | B5: 1 | C5: 15 | D5: 1 | E5: 4 | F5: 1 | G5: TRUE | H5: TRUE | I5: TRUE
A6: g.input | B6: 1 | C6: 2 | D6: 318 | E6: 3 | F6: 1 | G6: TRUE | H6: TRUE | I6: TRUE
A7: input | B7: 2 | C7: 9 | D7: 6 | E7: 6 | F7: 1 | G7: TRUE | H7: TRUE | I7: TRUE
A8: s.solverResult | B8: 1 | C8: 3 | D8: 27 | E8: 22 | F8: 1 | G8: TRUE | H8: TRUE | I8: TRUE
A9: solverResult | B9: 1 | C9: 8 | D9: 1 | E9: 3 | F9: 1 | G9: TRUE | H9: TRUE | I9: TRUE
A10: r.includes | B10: 1 | C10: 10 | D10: 608 | E10: 4 | F10: 1 | G10: TRUE | H10: TRUE | I10: TRUE
A11: includes | B11: 1 | C11: 16 | D11: 1 | E11: 3 | F11: 1 | G11: TRUE | H11: TRUE | I11: TRUE
A12: armModel | B12: 1 | C12: 14 | D12: 1 | E12: 4 | F12: 100021 | G12: FALSE | H12: FALSE | I12: TRUE
A13: armModel | B13: 1 | C13: 14 | D13: 1 | E13: 4 | F13: 100021 | G13: FALSE | H13: FALSE | I13: TRUE
A14: armModel | B14: 1 | C14: 14 | D14: 1 | E14: 4 | F14: 100021 | G14: FALSE | H14: FALSE | I14: TRUE
... A793: AdoptionAd | B793: 1 | C793: 1 | D793: 1 | E793: 36 | F793: 1 | G793: FALSE | H793: FALSE | I793: TRUE

Sheet gen - syn - large
A1: GeomagicTouch | B1: 47 | C1: 802 | D1: 793 | E1: 73 | F1: 1002 | G1: TRUE | H1: TRUE | I1: TRUE | K1: top 1 | L1: top 5 | M1: top 10 | N1: top 1 | O1: top 5 | P1: top 10 | Q1: top 1 | R1: top 5 | S1: top 10
A2: force | B2: 86 | C2: 798 | D2: 834 | E2: 11 | F2: 100021 | G2: TRUE | H2: TRUE | I2: TRUE | K2: =COUNTIF(B1:B1000,"=1") -> 83 | L2: =COUNTIF(B1:B1000,"<=5") -> 340 | M2: =COUNTIF(B1:B1000,"<=10") -> 407 | N2: =COUNTIF(D1:D1000,"=1") -> 0 | O2: =COUNTIF(D1:D1000,"<=5") -> 0 | P2: =COUNTIF(D1:D1000,"<=10") -> 0 | Q2: =COUNTIF(E1:E1000,"=1") -> 83 | R2: =COUNTIF(E1:E1000,"<=5") -> 214 | S2: =COUNTIF(E1:E1000,"<=10") -> 267
A3: Robot | B3: 66 | C3: 829 | D3: 813 | E3: 8 | F3: 1002 | G3: TRUE | H3: TRUE | I3: TRUE
A4: solverResult | B4: 15 | C4: 982 | D4: 984 | E4: 69 | F4: 1 | G4: TRUE | H4: TRUE | I4: TRUE
A5: output | B5: 92 | C5: 824 | D5: 841 | E5: 17 | F5: 100021 | G5: TRUE | H5: TRUE | I5: TRUE
A6: armModel | B6: 2 | C6: 884 | D6: 933 | E6: 31 | F6: 1 | G6: TRUE | H6: TRUE | I6: TRUE
A7: input | B7: 10 | C7: 868 | D7: 889 | E7: 13 | F7: 1 | G7: TRUE | H7: TRUE | I7: TRUE
A8: solverResult | B8: 15 | C8: 894 | D8: 896 | E8: 67 | F8: 1 | G8: TRUE | H8: TRUE | I8: TRUE
A9: includes | B9: 9 | C9: 848 | D9: 869 | E9: 33 | F9: 1 | G9: TRUE | H9: TRUE | I9: TRUE
A10: effectorType | B10: 85 | C10: 797 | D10: 833 | E10: 64 | F10: 100021 | G10: TRUE | H10: TRUE | I10: TRUE
A11: effectorType | B11: 85 | C11: 797 | D11: 833 | E11: 64 | F11: 100021 | G11: TRUE | H11: TRUE | I11: TRUE
A12: effectorType | B12: 85 | C12: 797 | D12: 833 | E12: 64 | F12: 100021 | G12: TRUE | H12: TRUE | I12: TRUE
A13: assigned | B13: 5 | C13: 782 | D13: 831 | E13: 31 | F13: 1 | G13: TRUE | H13: TRUE | I13: TRUE
A14: assigned | B14: 5 | C14: 782 | D14: 831 | E14: 31 | F14: 1 | G14: TRUE | H14: TRUE | I14: TRUE
... A611: Publication | B611: 26 | C611: 1619 | D611: 1599 | E611: 77 | F611: 1 | G611: TRUE | H611: TRUE | I611: TRUE

Sheet gen - first - large
A1: (ArmAngle-armangle) | B1: 1 | C1: 243 | D1: 216 | E1: 149 | F1: 1002 | G1: FALSE | H1: FALSE | I1: TRUE | K1: top 1 | L1: top 5 | M1: top 10 | N1: top 1 | O1: top 5 | P1: top 10 | Q1: top 1 | R1: top 5 | S1: top 10
A2: force | B2: 86 | C2: 798 | D2: 834 | E2: 11 | F2: 100021 | G2: TRUE | H2: TRUE | I2: TRUE | K2: =COUNTIF(B1:B1000,"=1") -> 290 | L2: =COUNTIF(B1:B1000,"<=5") -> 528 | M2: =COUNTIF(B1:B1000,"<=10") -> 588 | N2: =COUNTIF(D1:D1000,"=1") -> 0 | O2: =COUNTIF(D1:D1000,"<=5") -> 0 | P2: =COUNTIF(D1:D1000,"<=10") -> 0 | Q2: =COUNTIF(E1:E1000,"=1") -> 133 | R2: =COUNTIF(E1:E1000,"<=5") -> 213 | S2: =COUNTIF(E1:E1000,"<=10") -> 327
A3: (ArmAngle-armangle) | B3: 1 | C3: 243 | D3: 216 | E3: 149 | F3: 1002 | G3: FALSE | H3: FALSE | I3: TRUE
A4: solverResult | B4: 15 | C4: 982 | D4: 984 | E4: 69 | F4: 1 | G4: TRUE | H4: TRUE | I4: TRUE
A5: (none->none) | B5: 26 | C5: 569 | D5: 658 | E5: 52 | F5: 100021 | G5: FALSE | H5: FALSE | I5: TRUE
A6: anglelimit | B6: 1 | C6: 881 | D6: 932 | E6: 40 | F6: 1 | G6: FALSE | H6: FALSE | I6: TRUE
A7: input | B7: 10 | C7: 868 | D7: 889 | E7: 13 | F7: 1 | G7: TRUE | H7: TRUE | I7: TRUE
A8: solverResult | B8: 15 | C8: 894 | D8: 896 | E8: 67 | F8: 1 | G8: TRUE | H8: TRUE | I8: TRUE
A9: includes | B9: 9 | C9: 848 | D9: 869 | E9: 33 | F9: 1 | G9: TRUE | H9: TRUE | I9: TRUE
A10: (none->none) | B10: 26 | C10: 569 | D10: 658 | E10: 52 | F10: 100021 | G10: FALSE | H10: FALSE | I10: TRUE
A11: (none->none) | B11: 26 | C11: 569 | D11: 658 | E11: 52 | F11: 100021 | G11: FALSE | H11: FALSE | I11: TRUE
A12: (none->none) | B12: 26 | C12: 569 | D12: 658 | E12: 52 | F12: 100021 | G12: FALSE | H12: FALSE | I12: TRUE
A13: assigned | B13: 5 | C13: 782 | D13: 831 | E13: 31 | F13: 1 | G13: TRUE | H13: TRUE | I13: TRUE
A14: assigned | B14: 5 | C14: 782 | D14: 831 | E14: 31 | F14: 1 | G14: TRUE | H14: TRUE | I14: TRUE
... A754: AdoptionAd | B754: 1 | C754: 1572 | D754: 1572 | E754: 62 | F754: 1 | G754: FALSE | H754: FALSE | I754: TRUE
